Workbook

Sheet Rules
A1: FIF8A World Cup 2026
A2: =MID(CELL("filename",A1),FIND("]",CELL("filename",A1))+1,50) -> Rules
B10: Internal rules
B12: 1. Fill in your name, surname and office in the
B13: ='Player Template'!A2 -> Player Template
B15: 2. Fill your predictions for the different groups, the group table will be filled automatically depending on your predictions.
B17: 3. This year we introduce rates to all matches based on actual FIFA Rankings. Points for the standing will be attributed as followed:
C19: 6 | D19: points for each good pronostic (winner or draw) multiplied by the rate
C21: 2 | D21: additional point if you have the right goal difference between the two teams (you predicted A wining 1-0 to B and the final score is 2-1 for A)
C23: 3 | D23: additional points if you predicted the right score
B25: ="Everyone can thus win "&SUM($C$19:$C$23)&" points per game." -> Everyone can thus win 11 points per game.
B27: In addition, there will be points awarded based on your global predictive performance for each group:
C29: 30 | D29: points per group where you predicted the 2 teams going to the knock-out stage (in any order)
C31: 60 | D31: additional points if you predicted the right group table (in the right order 1,2,3 and 4) ie you win 15 points in total
B34: 4. Fill your prediction for the final teams that will remain at the latest stages of the competition in
B35: ='Last 8 teams predictions'!A2 -> Last 8 teams predictions
C37: 20 | D37: points per correct guessed team going into the quarter-finals
C39: 40 | D39: points per correct guessed team going into the semi-finals
C41: 60 | D41: points per correct guessed team going into the final
C43: 100 | D43: points if you found the World Cup champion in advance

Sheet Player Template
A1: FIF8A World Cup 2026
A2: =MID(CELL("filename",A1),FIND("]",CELL("filename",A1))+1,50) -> Player Template
B3: Tab Check | G3: GLOBAL CHECK
B4: =IF(SUM(A27:A120)>0,"Uncomplete","OK") -> Uncomplete | G4: =IF(AND('Player Template'!$B$4="OK",'Last 8 teams predictions'!$F$4="OK"),"OK","Uncomplete") -> Uncomplete
F6: Average rate | G6: Average | H6: =AVERAGE(H27:H123) -> 2.8340898 | K6: =AVERAGE(K27:K123) -> 4.3045843 | N6: =AVERAGE(N27:N123) -> 3.3689678 | AF6: Dispersion | AI6: =(_xlfn.MAXIFS('FIFA rankings'!$D$15:$D$62,'FIFA rankings'!$C$15:$C$62,TRUE)-_xlfn.MINIFS('FIFA rankings'!$D$15:$D$62,'FIFA rankings'!$C$15:$C$62,TRUE))*4 -> 2383
F7: Max rate | G7: Max | H7: =MAX(H27:H123) -> 7.4829528 | K7: =MAX(K27:K123) -> 5.5980834 | N7: =MAX(N27:N123) -> 8.0463535 | AF7: Expected goals per team per game | AI7: 1.4
F8: Min rate | G8: Min | H8: =MIN(H27:H123) -> 1.4397861 | K8: =MIN(K27:K123) -> 3.9557544 | N8: =MIN(N27:N123) -> 1.4728545
F9: Group | H9: Rate A | K9: Rate Draw | N9: Rate B | Q9: Time | R9: Team 1 | S9: Score Team 1 | T9: Score Team 2 | U9: Team 2
G12: Name
G15: Surname
G18: Office
G21: Email
AN25: Outcome probability
F26: Group A | G26: =$F26 & " / Odds" -> Group A / Odds | P26: =$F26 & " / Results" -> Group A / Results | X26: Ranking | Y26: Pts | Z26: GF | AA26: GA | AB26: ="+/-" -> +/- | AE26: Equipe A | AF26: Equipe B | AG26: Pts A | AH26: Pts B | AI26: Diff. | AK26: xG A | AL26: xG B | AN26: A | AO26: Draw | AP26: B | BD26: Rank | BE26: Team | BF26: Pts | BG26: GF | BH26: GA | BI26: GD | BJ26: Ag1 | BK26: Ag2 | BL26: Ag3 | BM26: Ag4 | BN26: Sp1 | BO26: Sp2 | BP26: Sp3 | BQ26: Sp4 | BR26: T123 | BS26: T124 | BT26: T134 | BU26: T234 | BV26: Rk1 | BW26: Rk2 | BX26: Rk3 | BY26: Rk4 | BZ26: T1234 | CA26: T123 | CB26: T124 | CC26: T134 | CD26: T234 | CE26: T12 | CF26: T13 | CG26: T14 | CH26: T23 | CI26: T24 | CJ26: T34 | CK26: NoT | CL26: sRk1 | CM26: sRk2 | CN26: sRk3 | CO26: sRk4
A27: =IF(OR(ISBLANK(S27),ISBLANK(T27)),1,0) -> 1 | C27: 1 | D27: A1 | E27: Group | F27: Group A | G27: =R27 -> Mexico | H27: =AN27 -> 1.872786 | J27: Draw | K27: =AO27 -> 4.2977309 | M27: =U27 -> South Africa | N27: =AP27 -> 4.2954634 | P27: 46184 | Q27: 0.875 | R27: Mexico | U27: South Africa | W27: =BA27 -> 1 | X27: =INDEX(BE27:BE30,MATCH(BC27,$BD27:$BD30,0)) -> Mexico | Y27: =INDEX(BF27:BF30,MATCH(BC27,$BD27:$BD30,0)) -> 0 | Z27: =INDEX(BG27:BG30,MATCH(BC27,$BD27:$BD30,0)) -> 0 | AA27: =INDEX(BH27:BH30,MATCH(BC27,$BD27:$BD30,0)) -> 0 | AB27: =INDEX(BI27:BI30,MATCH(BC27,$BD27:$BD30,0)) -> 0 | AE27: =R27 -> Mexico | AF27: =U27 -> South Africa | AG27: =_xlfn.XLOOKUP(AE27,'FIFA rankings'!$B:$B,'FIFA rankings'!$D:$D) -> 1681.03 | AH27: =_xlfn.XLOOKUP(AF27,'FIFA rankings'!$B:$B,'FIFA rankings'!$D:$D) -> 1429.73 | AI27: =IFERROR(AG27-AH27,"n.a.") -> 251.3 | AK27: =IFERROR($AI$7*POWER(10,$AI27/$AI$6),"n.a.") -> 1.7847745 | AL27: =IFERROR($AI$7*POWER(10,-$AI27/$AI$6),"n.a.") -> 1.098178 | AN27: {=1/SUMPRODUCT(_xlfn.POISSON.DIST(ROW($1:$8)-1,$AK27,FALSE)*_xlfn.POISSON.DIST(TRANSPOSE(ROW($1:$8)-1),$AL27,FALSE)*((ROW($1:$8)-1)>(TRANSPOSE(ROW($1:$8)-1))))} -> 1.872786 | AO27: {=1/SUMPRODUCT(_xlfn.POISSON.DIST(ROW($1:$8)-1,$AK27,FALSE)*_xlfn.POISSON.DIST(TRANSPOSE(ROW($1:$8)-1),$AL27,FALSE)*((ROW($1:$8)-1)=(TRANSPOSE(ROW($1:$8)-1))))} -> 4.2977309 | AP27: {=1/SUMPRODUCT(_xlfn.POISSON.DIST(ROW($1:$8)-1,$AK27,FALSE)*_xlfn.POISSON.DIST(TRANSPOSE(ROW($1:$8)-1),$AL27,FALSE)*((ROW($1:$8)-1)<(TRANSPOSE(ROW($1:$8)-1))))} -> 4.2954634 | AS27: =1-SUM(1/AN27,1/AO27,1/AP27) -> 0.00055150059 | BA27: 1 | BB27: =ROUND(BC27,0) -> 2 | BC27: =MIN(BD27:BD30) -> 2.45 | BD27: =SUM(BV27:BY27)+2.45 -> 2.45 | BE27: =R27 -> Mexico | BF27: =SUM(BJ27:BM27) -> 0 | BG27: =S27+S29+T31 -> 0 | BH27: =T27+T29+S31 -> 0 | BI27: =BG27-BH27 -> 0 | BJ27: x | BK27: =IF(ISBLANK(S27),0,IF(S27>T27,3,IF(S27=T27,1,0))) -> 0 | BL27: =IF(ISBLANK(S29),0,IF(S29>T29,3,IF(S29=T29,1,0))) -> 0 | BM27: =IF(ISBLANK(T31),0,IF(T31>S31,3,IF(T31=S31,1,0))) -> 0 | BN27: x | BO27: =(10*(BI27-BI28)+BG27-BG28>0) -> FALSE | BP27: =10*(BI27-BI29)+BG27-BG29>0 -> FALSE | BQ27: =10*(BI27-BI30)+BG27-BG30>0 -> FALSE | BR27: =10000*(BK27+BL27)+(S29-T29+S27-T27)*100+(S29+S27) -> 0 | BS27: =10000*(BK27+BM27)+(S27-T27+T31-S31)*100+(S27+T31) -> 0 | BT27: =10000*(BL27+BM27)+(T31-S31+S29-T29)*100+(T31+S29) -> 0 | BU27: x | BV27: x | BW27: =IF($BF27>$BF28,-0.5,IF($BF28>$BF27,0.5,IF(BO27,-0.5,IF(BN28,0.5,CM27)))) -> 0 | BX27: =IF($BF27>$BF29,-0.5,IF($BF29>$BF27,0.5,IF(BP27,-0.5,IF(BN29,0.5,CN27)))) -> 0 | BY27: =IF($BF27>$BF30,-0.5,IF($BF30>$BF27,0.5,IF(BQ27,-0.5,IF(BN30,0.5,CO27)))) -> 0 | BZ27: =AND(AND(BF27=BF28,BF28=BF29,BF29=BF30),AND(BG27=BG28,BG28=BG29,BG29=BG30),AND(BH27=BH28,BH28=BH29,BH29=BH30)) -> TRUE | CA27: =AND(NOT(BZ27),BF27=BF28,BF27=BF29,BG27=BG28,BG27=BG29,BH27=BH28,BH27=BH29) -> FALSE | CB27: =AND(NOT(BZ27),BF27=BF28,BF27=BF30,BG27=BG28,BG27=BG30,BH27=BH28,BH27=BH30) -> FALSE | CC27: =AND(NOT(BZ27),BF27=BF29,BF27=BF30,BG27=BG29,BG27=BG30,BH27=BH29,BH27=BH30) -> FALSE | CD27: =AND(NOT(BZ27),BF28=BF29,BF28=BF30,BG28=BG29,BG28=BG30,BH28=BH29,BH28=BH30) -> FALSE | CE27: =AND(NOT(BZ27),NOT(CA27),NOT(CB27),BF27=BF28,BG27=BG28,BH27=BH28) -> FALSE | CF27: =AND(NOT(BZ27),NOT(CA27),NOT(CC27),BF27=BF29,BG27=BG29,BH27=BH29) -> FALSE | CG27: =AND(NOT(BZ27),NOT(CB27),NOT(CC27),BF27=BF30,BG27=BG30,BH27=BH30) -> FALSE | CH27: =AND(NOT(BZ27),NOT(CA27),NOT(CD27),BF28=BF29,BG28=BG29) -> FALSE | CI27: =AND(NOT(BZ27),NOT(CB27),NOT(CD27),BF28=BF30,BG28=BG30,BH28=BH30) -> FALSE | CJ27: =AND(NOT(BZ27),NOT(CC27),NOT(CD27),BF29=BF30,BG29=BG30,BH29=BH30) -> FALSE | CK27: {=AND(NOT(BZ27:CJ27))} -> FALSE | CL27: x | CM27: =IF($CE27,IF(T27-S27<0,-0.5,IF(S27-T27<0,0.5,0)),IF($CA27,IF($BR27>$BR28,-0.5,IF($BR27<$BR28,0.5,0)),IF($CB27,IF($BS27>$BS28,-0.5, IF($BS27<$BS28,0.5,0)),0))) -> 0 | CN27: =IF($CF27,IF(T29-S29<0,-0.5,IF(S29-T29<0,0.5,0)),IF($CA27,IF($BR27>$BR29,-0.5,IF($BR27<$BR29,0.5,0)),IF($CC27,IF($BT27>$BT29,-0.5,IF($BT27<$BT29,0.5,0)),0))) -> 0 | CO27: =IF($CG27,IF(S31-T31<0,-0.5,IF(T31-S31<0,0.5,0)),IF($CB27,IF($BS27>$BS30,-0.5,IF($BS27<$BS30,0.5,0)),IF($CC27,IF($BT27>$BT30,-0.5, IF($BT27<$BT30,0.5,0)),0))) -> 0
A28: =IF(OR(ISBLANK(S28),ISBLANK(T28)),1,0) -> 1 | C28: 2 | D28: A2 | E28: Group | F28: Group A | G28: =R28 -> Korea Republic | H28: =AN28 -> 2.3360688 | J28: Draw | K28: =AO28 -> 3.9952172 | M28: =U28 -> Czechia | N28: =AP28 -> 3.1115488 | P28: 46185 | Q28: 0.16666667 | R28: Korea Republic | U28: Czechia | W28: =BA28 -> 1 | X28: =INDEX(BE27:BE30,MATCH(BC28,$BD27:$BD30,0)) -> South Africa | Y28: =INDEX(BF27:BF30,MATCH(BC28,$BD27:$BD30,0)) -> 0 | Z28: =INDEX(BG27:BG30,MATCH(BC28,$BD27:$BD30,0)) -> 0 | AA28: =INDEX(BH27:BH30,MATCH(BC28,$BD27:$BD30,0)) -> 0 | AB28: =INDEX(BI27:BI30,MATCH(BC28,$BD27:$BD30,0)) -> 0 | AE28: =R28 -> Korea Republic | AF28: =U28 -> Czechia | AG28: =_xlfn.XLOOKUP(AE28,'FIFA rankings'!$B:$B,'FIFA rankings'!$D:$D) -> 1588.66 | AH28: =_xlfn.XLOOKUP(AF28,'FIFA rankings'!$B:$B,'FIFA rankings'!$D:$D) -> 1501.38 | AI28: =IFERROR(AG28-AH28,"n.a.") -> 87.28 | AK28: =IFERROR($AI$7*POWER(10,$AI28/$AI$6),"n.a.") -> 1.5231902 | AL28: =IFERROR($AI$7*POWER(10,-$AI28/$AI$6),"n.a.") -> 1.286773 | AN28: {=1/SUMPRODUCT(_xlfn.POISSON.DIST(ROW($1:$8)-1,$AK28,FALSE)*_xlfn.POISSON.DIST(TRANSPOSE(ROW($1:$8)-1),$AL28,FALSE)*((ROW($1:$8)-1)>(TRANSPOSE(ROW($1:$8)-1))))} -> 2.3360688 | AO28: {=1/SUMPRODUCT(_xlfn.POISSON.DIST(ROW($1:$8)-1,$AK28,FALSE)*_xlfn.POISSON.DIST(TRANSPOSE(ROW($1:$8)-1),$AL28,FALSE)*((ROW($1:$8)-1)=(TRANSPOSE(ROW($1:$8)-1))))} -> 3.9952172 | AP28: {=1/SUMPRODUCT(_xlfn.POISSON.DIST(ROW($1:$8)-1,$AK28,FALSE)*_xlfn.POISSON.DIST(TRANSPOSE(ROW($1:$8)-1),$AL28,FALSE)*((ROW($1:$8)-1)<(TRANSPOSE(ROW($1:$8)-1))))} -> 3.1115488 | AS28: =1-SUM(1/AN28,1/AO28,1/AP28) -> 0.00024777226 | BA28: =IF(ROUND(BC28,0)=ROUND(BC27,0),BA27,2) -> 1 | BB28: =ROUND(BC28,0) -> 2 | BC28: =MAX(MIN(BD27:BD29),MIN(BD27,BD28,BD30),MIN(BD27,BD29,BD30),MIN(BD28:BD30)) -> 2.46 | BD28: =SUM(BV28:BY28)+2.46 -> 2.46 | BE28: =U27 -> South Africa | BF28: =SUM(BJ28:BM28) -> 0 | BG28: =T27+T30+S32 -> 0 | BH28: =S27+S30+T32 -> 0 | BI28: =BG28-BH28 -> 0 | BJ28: =IF(ISBLANK(T27),0,IF(BK27=3,0,IF(BK27=1,1,3))) -> 0 | BK28: x | BL28: =IF(ISBLANK(S32),0,IF(BK29=3,0,IF(BK29=1,1,3))) -> 0 | BM28: =IF(ISBLANK(T30),0,IF(T30>S30,3,IF(T30=S30,1,0))) -> 0 | BN28: =(10*(BI27-BI28)+BG27-BG28<0) -> FALSE | BO28: x | BP28: =10*(BI28-BI29)+BG28-BG29>0 -> FALSE | BQ28: =10*(BI28-BI30)+BG28-BG30>0 -> FALSE | BR28: =10000*(BJ28+BL28)+(T27-S27+S32-T32)*100+(T27+S32) -> 0 | BS28: =10000*(BJ28+BM28)+(T27-S27+T30-S30)*100+(T27+T30) -> 0 | BT28: x | BU28: =10000*(BL28+BM28)+(T30-S30+S32-T32)*100+(T30+S32) -> 0 | BV28: =-BW27 -> 0 | BW28: x | BX28: =IF($BF28>$BF29,-0.5,IF($BF29>$BF28,0.5,IF(BP28,-0.5,IF(BO29,0.5,CN28)))) -> 0 | BY28: =IF($BF28>$BF30,-0.5,IF($BF30>$BF28,0.5,IF(BQ28,-0.5,IF(BO30,0.5,CO28)))) -> 0 | CM28: x | CN28: =IF($CH27,IF(T32-S32<0,-0.5,IF(S32-T32<0,0.5,0)),IF($CA27,IF($BR28>$BR29,-0.5,IF($BR28<$BR29,0.5,0)),IF($CD27,IF($BU28>$BU29,-0.5,IF($BU28<$BU29,0.5,0)),0))) -> 0 | CO28: =IF($CI27,IF(S30-T30<0,-0.5,IF(T30-S30<0,0.5,0)),IF($CB27,IF($BS28>$BS30,-0.5,IF($BS28<$BS30,0.5,0)),IF($CD27,IF($BU28>$BU30,-0.5,IF($BU28<$BU30,0.5,0)),0))) -> 0
A29: =IF(OR(ISBLANK(S29),ISBLANK(T29)),1,0) -> 1 | C29: 25 | D29: A3 | E29: Group | F29: Group A | G29: =R29 -> Mexico | H29: =AN29 -> 2.3185202 | J29: Draw | K29: =AO29 -> 4.0000013 | M29: =U29 -> Korea Republic | N29: =AP29 -> 3.1403244 | P29: 46192 | Q29: 0.125 | R29: =R27 -> Mexico | U29: =R28 -> Korea Republic | W29: =BA29 -> 1 | X29: =INDEX(BE27:BE30,MATCH(BC29,$BD27:$BD30,0)) -> Korea Republic | Y29: =INDEX(BF27:BF30,MATCH(BC29,$BD27:$BD30,0)) -> 0 | Z29: =INDEX(BG27:BG30,MATCH(BC29,$BD27:$BD30,0)) -> 0 | AA29: =INDEX(BH27:BH30,MATCH(BC29,$BD27:$BD30,0)) -> 0 | AB29: =INDEX(BI27:BI30,MATCH(BC29,$BD27:$BD30,0)) -> 0 | AE29: =R29 -> Mexico | AF29: =U29 -> Korea Republic | AG29: =_xlfn.XLOOKUP(AE29,'FIFA rankings'!$B:$B,'FIFA rankings'!$D:$D) -> 1681.03 | AH29: =_xlfn.XLOOKUP(AF29,'FIFA rankings'!$B:$B,'FIFA rankings'!$D:$D) -> 1588.66 | AI29: =IFERROR(AG29-AH29,"n.a.") -> 92.37 | AK29: =IFERROR($AI$7*POWER(10,$AI29/$AI$6),"n.a.") -> 1.5307001 | AL29: =IFERROR($AI$7*POWER(10,-$AI29/$AI$6),"n.a.") -> 1.2804599 | AN29: {=1/SUMPRODUCT(_xlfn.POISSON.DIST(ROW($1:$8)-1,$AK29,FALSE)*_xlfn.POISSON.DIST(TRANSPOSE(ROW($1:$8)-1),$AL29,FALSE)*((ROW($1:$8)-1)>(TRANSPOSE(ROW($1:$8)-1))))} -> 2.3185202 | AO29: {=1/SUMPRODUCT(_xlfn.POISSON.DIST(ROW($1:$8)-1,$AK29,FALSE)*_xlfn.POISSON.DIST(TRANSPOSE(ROW($1:$8)-1),$AL29,FALSE)*((ROW($1:$8)-1)=(TRANSPOSE(ROW($1:$8)-1))))} -> 4.0000013 | AP29: {=1/SUMPRODUCT(_xlfn.POISSON.DIST(ROW($1:$8)-1,$AK29,FALSE)*_xlfn.POISSON.DIST(TRANSPOSE(ROW($1:$8)-1),$AL29,FALSE)*((ROW($1:$8)-1)<(TRANSPOSE(ROW($1:$8)-1))))} -> 3.1403244 | AS29: =1-SUM(1/AN29,1/AO29,1/AP29) -> 0.00025204346 | BA29: =IF(ROUND(BC29,0)=ROUND(BC28,0),BA28,3) -> 1 | BB29: =ROUND(BC29,0) -> 2 | BC29: =MIN(MAX(BD27:BD29),MAX(BD27,BD28,BD30),MAX(BD27,BD29,BD30),MAX(BD28:BD30)) -> 2.47 | BD29: =SUM(BV29:BY29)+2.47 -> 2.47 | BE29: =R28 -> Korea Republic | BF29: =SUM(BJ29:BM29) -> 0 | BG29: =S28+T29+T32 -> 0 | BH29: =T28+S29+S32 -> 0 | BI29: =BG29-BH29 -> 0 | BJ29: =IF(ISBLANK(T29),0,IF(BL27=3,0,IF(BL27=1,1,3))) -> 0 | BK29: =IF(ISBLANK(T32),0,IF(T32>S32,3,IF(T32=S32,1,0))) -> 0 | BL29: x | BM29: =IF(ISBLANK(S28),0,IF(S28>T28,3,IF(S28=T28,1,0))) -> 0 | BN29: =10*(BI27-BI29)+BG27-BG29<0 -> FALSE | BO29: =10*(BI28-BI29)+BG28-BG29<0 -> FALSE | BP29: x | BQ29: =10*(BI29-BI30)+BG29-BG30>0 -> FALSE | BR29: =10000*(BJ29+BK29)+(T29-S29+T32-S32)*100+(T29+T32) -> 0 | BS29: x | BT29: =10000*(BJ29+BM29)+(S28-T28+T29-S29)*100+(S28+T29) -> 0 | BU29: =10000*(BK29+BM29)+(S28-T28+T32-S32)*100+(S28+T32) -> 0 | BV29: =-BX27 -> 0 | BW29: =-BX28 -> 0 | BX29: x | BY29: =IF($BF29>$BF30,-0.5,IF($BF30>$BF29,0.5,IF(BQ29,-0.5,IF(BP30,0.5,CO29)))) -> 0 | CN29: x | CO29: =IF($CJ27,IF(T28-S28<0,-0.5,IF(S28-T28<0,0.5,0)),IF($CC27,IF($BT29>$BT30,-0.5,IF($BT29<$BT30,0.5,0)),IF($CD27,IF($BU29>$BU30,-0.5,IF($BU29<$BU30,0.5,0)),0))) -> 0
A30: =IF(OR(ISBLANK(S30),ISBLANK(T30)),1,0) -> 1 | C30: 28 | D30: A4 | E30: Group | F30: Group A | G30: =R30 -> Czechia | H30: =AN30 -> 2.3914628 | J30: Draw | K30: =AO30 -> 3.9822531 | M30: =U30 -> South Africa | N30: =AP30 -> 3.02576 | P30: 46191 | Q30: 0.75 | R30: =U28 -> Czechia | U30: =U27 -> South Africa | W30: =BA30 -> 1 | X30: =INDEX(BE27:BE30,MATCH(BC30,$BD27:$BD30,0)) -> Czechia | Y30: =INDEX(BF27:BF30,MATCH(BC30,$BD27:$BD30,0)) -> 0 | Z30: =INDEX(BG27:BG30,MATCH(BC30,$BD27:$BD30,0)) -> 0 | AA30: =INDEX(BH27:BH30,MATCH(BC30,$BD27:$BD30,0)) -> 0 | AB30: =INDEX(BI27:BI30,MATCH(BC30,$BD27:$BD30,0)) -> 0 | AE30: =R30 -> Czechia | AF30: =U30 -> South Africa | AG30: =_xlfn.XLOOKUP(AE30,'FIFA rankings'!$B:$B,'FIFA rankings'!$D:$D) -> 1501.38 | AH30: =_xlfn.XLOOKUP(AF30,'FIFA rankings'!$B:$B,'FIFA rankings'!$D:$D) -> 1429.73 | AI30: =IFERROR(AG30-AH30,"n.a.") -> 71.65 | AK30: =IFERROR($AI$7*POWER(10,$AI30/$AI$6),"n.a.") -> 1.500359 | AL30: =IFERROR($AI$7*POWER(10,-$AI30/$AI$6),"n.a.") -> 1.306354 | AN30: {=1/SUMPRODUCT(_xlfn.POISSON.DIST(ROW($1:$8)-1,$AK30,FALSE)*_xlfn.POISSON.DIST(TRANSPOSE(ROW($1:$8)-1),$AL30,FALSE)*((ROW($1:$8)-1)>(TRANSPOSE(ROW($1:$8)-1))))} -> 2.3914628 | AO30: {=1/SUMPRODUCT(_xlfn.POISSON.DIST(ROW($1:$8)-1,$AK30,FALSE)*_xlfn.POISSON.DIST(TRANSPOSE(ROW($1:$8)-1),$AL30,FALSE)*((ROW($1:$8)-1)=(TRANSPOSE(ROW($1:$8)-1))))} -> 3.9822531 | AP30: {=1/SUMPRODUCT(_xlfn.POISSON.DIST(ROW($1:$8)-1,$AK30,FALSE)*_xlfn.POISSON.DIST(TRANSPOSE(ROW($1:$8)-1),$AL30,FALSE)*((ROW($1:$8)-1)<(TRANSPOSE(ROW($1:$8)-1))))} -> 3.02576 | AS30: =1-SUM(1/AN30,1/AO30,1/AP30) -> 0.00023628607 | BA30: =IF(ROUND(BC30,0)=ROUND(BC29,0),BA29,4) -> 1 | BB30: =ROUND(BC30,0) -> 2 | BC30: =MAX(BD27:BD30) -> 2.48 | BD30: =SUM(BV30:BY30)+2.48 -> 2.48 | BE30: =U28 -> Czechia | BF30: =SUM(BJ30:BM30) -> 0 | BG30: =T28+S30+S31 -> 0 | BH30: =S28+T30+T31 -> 0 | BI30: =BG30-BH30 -> 0 | BJ30: =IF(ISBLANK(S31),0,IF(BM27=3,0,IF(BM27=1,1,3))) -> 0 | BK30: =IF(ISBLANK(S30),0,IF(BM28=3,0,IF(BM28=1,1,3))) -> 0 | BL30: =IF(ISBLANK(T28),0,IF(BM29=3,0,IF(BM29=1,1,3))) -> 0 | BM30: x | BN30: =10*(BI27-BI30)+BG27-BG30<0 -> FALSE | BO30: =10*(BI28-BI30)+BG28-BG30<0 -> FALSE | BP30: =10*(BI29-BI30)+BG29-BG30<0 -> FALSE | BQ30: x | BR30: x | BS30: =10000*(BJ30+BK30)+(S30-T30+S31-T31)*100+(S30+S31) -> 0 | BT30: =10000*(BJ30+BL30)+(S31-T31+T28-S28)*100+(S31+T28) -> 0 | BU30: =10000*(BK30+BL30)+(S30-T30+T28-S28)*100+(S30+T28) -> 0 | BV30: =-BY27 -> 0 | BW30: =-BY28 -> 0 | BX30: =-BY29 -> 0 | BY30: x | CO30: x
A31: =IF(OR(ISBLANK(S31),ISBLANK(T31)),1,0) -> 1 | C31: 53 | E31: Group | F31: Group A | G31: =R31 -> Czechia | H31: =AN31 -> 3.7063186 | J31: Draw | K31: =AO31 -> 4.1264874 | M31: =U31 -> Mexico | N31: =AP31 -> 2.0513562 | P31: 46198 | Q31: 0.125 | R31: =U28 -> Czechia | U31: =R27 -> Mexico | X31: =IF(OR(W29<3,W28<2),"TIRAGE AU SORT !!!"," ") -> TIRAGE AU SORT !!! | AE31: =R31 -> Czechia | AF31: =U31 -> Mexico | AG31: =_xlfn.XLOOKUP(AE31,'FIFA rankings'!$B:$B,'FIFA rankings'!$D:$D) -> 1501.38 | AH31: =_xlfn.XLOOKUP(AF31,'FIFA rankings'!$B:$B,'FIFA rankings'!$D:$D) -> 1681.03 | AI31: =IFERROR(AG31-AH31,"n.a.") -> -179.65 | AK31: =IFERROR($AI$7*POWER(10,$AI31/$AI$6),"n.a.") -> 1.1769008 | AL31: =IFERROR($AI$7*POWER(10,-$AI31/$AI$6),"n.a.") -> 1.665391 | AN31: {=1/SUMPRODUCT(_xlfn.POISSON.DIST(ROW($1:$8)-1,$AK31,FALSE)*_xlfn.POISSON.DIST(TRANSPOSE(ROW($1:$8)-1),$AL31,FALSE)*((ROW($1:$8)-1)>(TRANSPOSE(ROW($1:$8)-1))))} -> 3.7063186 | AO31: {=1/SUMPRODUCT(_xlfn.POISSON.DIST(ROW($1:$8)-1,$AK31,FALSE)*_xlfn.POISSON.DIST(TRANSPOSE(ROW($1:$8)-1),$AL31,FALSE)*((ROW($1:$8)-1)=(TRANSPOSE(ROW($1:$8)-1))))} -> 4.1264874 | AP31: {=1/SUMPRODUCT(_xlfn.POISSON.DIST(ROW($1:$8)-1,$AK31,FALSE)*_xlfn.POISSON.DIST(TRANSPOSE(ROW($1:$8)-1),$AL31,FALSE)*((ROW($1:$8)-1)<(TRANSPOSE(ROW($1:$8)-1))))} -> 2.0513562 | AS31: =1-SUM(1/AN31,1/AO31,1/AP31) -> 0.0003712508
A32: =IF(OR(ISBLANK(S32),ISBLANK(T32)),1,0) -> 1 | C32: 54 | E32: Group | F32: Group A | G32: =R32 -> South Africa | H32: =AN32 -> 3.5584846 | J32: Draw | K32: =AO32 -> 4.0886531 | M32: =U32 -> Korea Republic | N32: =AP32 -> 2.1094027 | P32: 46198 | Q32: 0.125 | R32: =U27 -> South Africa | U32: =R28 -> Korea Republic | AE32: =R32 -> South Africa | AF32: =U32 -> Korea Republic | AG32: =_xlfn.XLOOKUP(AE32,'FIFA rankings'!$B:$B,'FIFA rankings'!$D:$D) -> 1429.73 | AH32: =_xlfn.XLOOKUP(AF32,'FIFA rankings'!$B:$B,'FIFA rankings'!$D:$D) -> 1588.66 | AI32: =IFERROR(AG32-AH32,"n.a.") -> -158.93 | AK32: =IFERROR($AI$7*POWER(10,$AI32/$AI$6),"n.a.") -> 1.2007008 | AL32: =IFERROR($AI$7*POWER(10,-$AI32/$AI$6),"n.a.") -> 1.6323801 | AN32: {=1/SUMPRODUCT(_xlfn.POISSON.DIST(ROW($1:$8)-1,$AK32,FALSE)*_xlfn.POISSON.DIST(TRANSPOSE(ROW($1:$8)-1),$AL32,FALSE)*((ROW($1:$8)-1)>(TRANSPOSE(ROW($1:$8)-1))))} -> 3.5584846 | AO32: {=1/SUMPRODUCT(_xlfn.POISSON.DIST(ROW($1:$8)-1,$AK32,FALSE)*_xlfn.POISSON.DIST(TRANSPOSE(ROW($1:$8)-1),$AL32,FALSE)*((ROW($1:$8)-1)=(TRANSPOSE(ROW($1:$8)-1))))} -> 4.0886531 | AP32: {=1/SUMPRODUCT(_xlfn.POISSON.DIST(ROW($1:$8)-1,$AK32,FALSE)*_xlfn.POISSON.DIST(TRANSPOSE(ROW($1:$8)-1),$AL32,FALSE)*((ROW($1:$8)-1)<(TRANSPOSE(ROW($1:$8)-1))))} -> 2.1094027 | AS32: =1-SUM(1/AN32,1/AO32,1/AP32) -> 0.00033433318
F34: Group B | G34: =$F34 & " / Odds" -> Group B / Odds | P34: =$F34 & " / Results" -> Group B / Results | X34: =X26 -> Ranking | Y34: Pts | Z34: GF | AA34: GA | AB34: ="+/-" -> +/- | BD34: Rank | BE34: Team | BF34: Pts | BG34: GF | BH34: GA | BI34: GD | BJ34: Ag1 | BK34: Ag2 | BL34: Ag3 | BM34: Ag4 | BN34: Sp1 | BO34: Sp2 | BP34: Sp3 | BQ34: Sp4 | BR34: T123 | BS34: T124 | BT34: T134 | BU34: T234 | BV34: Rk1 | BW34: Rk2 | BX34: Rk3 | BY34: Rk4 | BZ34: T1234 | CA34: T123 | CB34: T124 | CC34: T134 | CD34: T234 | CE34: T12 | CF34: T13 | CG34: T14 | CH34: T23 | CI34: T24 | CJ34: T34 | CK34: NoT | CL34: sRk1 | CM34: sRk2 | CN34: sRk3 | CO34: sRk4
A35: =IF(OR(ISBLANK(S35),ISBLANK(T35)),1,0) -> 1 | C35: 3 | D35: B1 | E35: Group | F35: Group B | G35: =R35 -> Canada | H35: =AN35 -> 2.0762168 | J35: Draw | K35: =AO35 -> 4.1094181 | M35: =U35 -> Bosnia and Herzegovina | N35: =AP35 -> 3.6409075 | P35: 46185 | Q35: 0.875 | R35: Canada | U35: Bosnia and Herzegovina | W35: =BA35 -> 1 | X35: =INDEX(BE35:BE38,MATCH(BC35,$BD35:$BD38,0)) -> Canada | Y35: =INDEX(BF35:BF38,MATCH(BC35,$BD35:$BD38,0)) -> 0 | Z35: =INDEX(BG35:BG38,MATCH(BC35,$BD35:$BD38,0)) -> 0 | AA35: =INDEX(BH35:BH38,MATCH(BC35,$BD35:$BD38,0)) -> 0 | AB35: =INDEX(BI35:BI38,MATCH(BC35,$BD35:$BD38,0)) -> 0 | AE35: =R35 -> Canada | AF35: =U35 -> Bosnia and Herzegovina | AG35: =_xlfn.XLOOKUP(AE35,'FIFA rankings'!$B:$B,'FIFA rankings'!$D:$D) -> 1556.48 | AH35: =_xlfn.XLOOKUP(AF35,'FIFA rankings'!$B:$B,'FIFA rankings'!$D:$D) -> 1385.84 | AI35: =IFERROR(AG35-AH35,"n.a.") -> 170.64 | AK35: =IFERROR($AI$7*POWER(10,$AI35/$AI$6),"n.a.") -> 1.6509551 | AL35: =IFERROR($AI$7*POWER(10,-$AI35/$AI$6),"n.a.") -> 1.1871916 | AN35: {=1/SUMPRODUCT(_xlfn.POISSON.DIST(ROW($1:$8)-1,$AK35,FALSE)*_xlfn.POISSON.DIST(TRANSPOSE(ROW($1:$8)-1),$AL35,FALSE)*((ROW($1:$8)-1)>(TRANSPOSE(ROW($1:$8)-1))))} -> 2.0762168 | AO35: {=1/SUMPRODUCT(_xlfn.POISSON.DIST(ROW($1:$8)-1,$AK35,FALSE)*_xlfn.POISSON.DIST(TRANSPOSE(ROW($1:$8)-1),$AL35,FALSE)*((ROW($1:$8)-1)=(TRANSPOSE(ROW($1:$8)-1))))} -> 4.1094181 | AP35: {=1/SUMPRODUCT(_xlfn.POISSON.DIST(ROW($1:$8)-1,$AK35,FALSE)*_xlfn.POISSON.DIST(TRANSPOSE(ROW($1:$8)-1),$AL35,FALSE)*((ROW($1:$8)-1)<(TRANSPOSE(ROW($1:$8)-1))))} -> 3.6409075 | AS35: =1-SUM(1/AN35,1/AO35,1/AP35) -> 0.00035446292 | BA35: 1 | BB35: =ROUND(BC35,0) -> 2 | BC35: =MIN(BD35:BD38) -> 2.45 | BD35: =SUM(BV35:BY35)+2.45 -> 2.45 | BE35: =R35 -> Canada | BF35: =SUM(BJ35:BM35) -> 0 | BG35: =S35+S37+T39 -> 0 | BH35: =T35+T37+S39 -> 0 | BI35: =BG35-BH35 -> 0 | BJ35: x | BK35: =IF(ISBLANK(S35),0,IF(S35>T35,3,IF(S35=T35,1,0))) -> 0 | BL35: =IF(ISBLANK(S37),0,IF(S37>T37,3,IF(S37=T37,1,0))) -> 0 | BM35: =IF(ISBLANK(T39),0,IF(T39>S39,3,IF(T39=S39,1,0))) -> 0 | BN35: x | BO35: =(10*(BI35-BI36)+BG35-BG36>0) -> FALSE | BP35: =10*(BI35-BI37)+BG35-BG37>0 -> FALSE | BQ35: =10*(BI35-BI38)+BG35-BG38>0 -> FALSE | BR35: =10000*(BK35+BL35)+(S37-T37+S35-T35)*100+(S37+S35) -> 0 | BS35: =10000*(BK35+BM35)+(S35-T35+T39-S39)*100+(S35+T39) -> 0 | BT35: =10000*(BL35+BM35)+(T39-S39+S37-T37)*100+(T39+S37) -> 0 | BU35: x | BV35: x | BW35: =IF($BF35>$BF36,-0.5,IF($BF36>$BF35,0.5,IF(BO35,-0.5,IF(BN36,0.5,CM35)))) -> 0 | BX35: =IF($BF35>$BF37,-0.5,IF($BF37>$BF35,0.5,IF(BP35,-0.5,IF(BN37,0.5,CN35)))) -> 0 | BY35: =IF($BF35>$BF38,-0.5,IF($BF38>$BF35,0.5,IF(BQ35,-0.5,IF(BN38,0.5,CO35)))) -> 0 | BZ35: =AND(AND(BF35=BF36,BF36=BF37,BF37=BF38),AND(BG35=BG36,BG36=BG37,BG37=BG38),AND(BH35=BH36,BH36=BH37,BH37=BH38)) -> TRUE | CA35: =AND(NOT(BZ35),BF35=BF36,BF35=BF37,BG35=BG36,BG35=BG37,BH35=BH36,BH35=BH37) -> FALSE | CB35: =AND(NOT(BZ35),BF35=BF36,BF35=BF38,BG35=BG36,BG35=BG38,BH35=BH36,BH35=BH38) -> FALSE | CC35: =AND(NOT(BZ35),BF35=BF37,BF35=BF38,BG35=BG37,BG35=BG38,BH35=BH37,BH35=BH38) -> FALSE | CD35: =AND(NOT(BZ35),BF36=BF37,BF36=BF38,BG36=BG37,BG36=BG38,BH36=BH37,BH36=BH38) -> FALSE | CE35: =AND(NOT(BZ35),NOT(CA35),NOT(CB35),BF35=BF36,BG35=BG36,BH35=BH36) -> FALSE | CF35: =AND(NOT(BZ35),NOT(CA35),NOT(CC35),BF35=BF37,BG35=BG37,BH35=BH37) -> FALSE | CG35: =AND(NOT(BZ35),NOT(CB35),NOT(CC35),BF35=BF38,BG35=BG38,BH35=BH38) -> FALSE | CH35: =AND(NOT(BZ35),NOT(CA35),NOT(CD35),BF36=BF37,BG36=BG37) -> FALSE | CI35: =AND(NOT(BZ35),NOT(CB35),NOT(CD35),BF36=BF38,BG36=BG38,BH36=BH38) -> FALSE | CJ35: =AND(NOT(BZ35),NOT(CC35),NOT(CD35),BF37=BF38,BG37=BG38,BH37=BH38) -> FALSE | CK35: {=AND(NOT(BZ35:CJ35))} -> FALSE | CL35: x | CM35: =IF($CE35,IF(T35-S35<0,-0.5,IF(S35-T35<0,0.5,0)),IF($CA35,IF($BR35>$BR36,-0.5,IF($BR35<$BR36,0.5,0)),IF($CB35,IF($BS35>$BS36,-0.5, IF($BS35<$BS36,0.5,0)),0))) -> 0 | CN35: =IF($CF35,IF(T37-S37<0,-0.5,IF(S37-T37<0,0.5,0)),IF($CA35,IF($BR35>$BR37,-0.5,IF($BR35<$BR37,0.5,0)),IF($CC35,IF($BT35>$BT37,-0.5,IF($BT35<$BT37,0.5,0)),0))) -> 0 | CO35: =IF($CG35,IF(S39-T39<0,-0.5,IF(T39-S39<0,0.5,0)),IF($CB35,IF($BS35>$BS38,-0.5,IF($BS35<$BS38,0.5,0)),IF($CC35,IF($BT35>$BT38,-0.5, IF($BT35<$BT38,0.5,0)),0))) -> 0
A36: =IF(OR(ISBLANK(S36),ISBLANK(T36)),1,0) -> 1 | C36: 8 | D36: B2 | E36: Group | F36: Group B | G36: =R36 -> Qatar | H36: =AN36 -> 3.8176095 | J36: Draw | K36: =AO36 -> 4.1566024 | M36: =U36 -> Switzerland | N36: =AP36 -> 2.011775 | P36: 46186 | Q36: 0.875 | R36: Qatar | U36: Switzerland | W36: =BA36 -> 1 | X36: =INDEX(BE35:BE38,MATCH(BC36,$BD35:$BD38,0)) -> Bosnia and Herzegovina | Y36: =INDEX(BF35:BF38,MATCH(BC36,$BD35:$BD38,0)) -> 0 | Z36: =INDEX(BG35:BG38,MATCH(BC36,$BD35:$BD38,0)) -> 0 | AA36: =INDEX(BH35:BH38,MATCH(BC36,$BD35:$BD38,0)) -> 0 | AB36: =INDEX(BI35:BI38,MATCH(BC36,$BD35:$BD38,0)) -> 0 | AE36: =R36 -> Qatar | AF36: =U36 -> Switzerland | AG36: =_xlfn.XLOOKUP(AE36,'FIFA rankings'!$B:$B,'FIFA rankings'!$D:$D) -> 1454.96 | AH36: =_xlfn.XLOOKUP(AF36,'FIFA rankings'!$B:$B,'FIFA rankings'!$D:$D) -> 1649.4 | AI36: =IFERROR(AG36-AH36,"n.a.") -> -194.44 | AK36: =IFERROR($AI$7*POWER(10,$AI36/$AI$6),"n.a.") -> 1.1602015 | AL36: =IFERROR($AI$7*POWER(10,-$AI36/$AI$6),"n.a.") -> 1.6893618 | AN36: {=1/SUMPRODUCT(_xlfn.POISSON.DIST(ROW($1:$8)-1,$AK36,FALSE)*_xlfn.POISSON.DIST(TRANSPOSE(ROW($1:$8)-1),$AL36,FALSE)*((ROW($1:$8)-1)>(TRANSPOSE(ROW($1:$8)-1))))} -> 3.8176095 | AO36: {=1/SUMPRODUCT(_xlfn.POISSON.DIST(ROW($1:$8)-1,$AK36,FALSE)*_xlfn.POISSON.DIST(TRANSPOSE(ROW($1:$8)-1),$AL36,FALSE)*((ROW($1:$8)-1)=(TRANSPOSE(ROW($1:$8)-1))))} -> 4.1566024 | AP36: {=1/SUMPRODUCT(_xlfn.POISSON.DIST(ROW($1:$8)-1,$AK36,FALSE)*_xlfn.POISSON.DIST(TRANSPOSE(ROW($1:$8)-1),$AL36,FALSE)*((ROW($1:$8)-1)<(TRANSPOSE(ROW($1:$8)-1))))} -> 2.011775 | AS36: =1-SUM(1/AN36,1/AO36,1/AP36) -> 0.00040139608 | BA36: =IF(ROUND(BC36,0)=ROUND(BC35,0),BA35,2) -> 1 | BB36: =ROUND(BC36,0) -> 2 | BC36: =MAX(MIN(BD35:BD37),MIN(BD35,BD36,BD38),MIN(BD35,BD37,BD38),MIN(BD36:BD38)) -> 2.46 | BD36: =SUM(BV36:BY36)+2.46 -> 2.46 | BE36: =U35 -> Bosnia and Herzegovina | BF36: =SUM(BJ36:BM36) -> 0 | BG36: =T35+T38+S40 -> 0 | BH36: =S35+S38+T40 -> 0 | BI36: =BG36-BH36 -> 0 | BJ36: =IF(ISBLANK(T35),0,IF(BK35=3,0,IF(BK35=1,1,3))) -> 0 | BK36: x | BL36: =IF(ISBLANK(S40),0,IF(BK37=3,0,IF(BK37=1,1,3))) -> 0 | BM36: =IF(ISBLANK(T38),0,IF(T38>S38,3,IF(T38=S38,1,0))) -> 0 | BN36: =(10*(BI35-BI36)+BG35-BG36<0) -> FALSE | BO36: x | BP36: =10*(BI36-BI37)+BG36-BG37>0 -> FALSE | BQ36: =10*(BI36-BI38)+BG36-BG38>0 -> FALSE | BR36: =10000*(BJ36+BL36)+(T35-S35+S40-T40)*100+(T35+S40) -> 0 | BS36: =10000*(BJ36+BM36)+(T35-S35+T38-S38)*100+(T35+T38) -> 0 | BT36: x | BU36: =10000*(BL36+BM36)+(T38-S38+S40-T40)*100+(T38+S40) -> 0 | BV36: =-BW35 -> 0 | BW36: x | BX36: =IF($BF36>$BF37,-0.5,IF($BF37>$BF36,0.5,IF(BP36,-0.5,IF(BO37,0.5,CN36)))) -> 0 | BY36: =IF($BF36>$BF38,-0.5,IF($BF38>$BF36,0.5,IF(BQ36,-0.5,IF(BO38,0.5,CO36)))) -> 0 | CM36: x | CN36: =IF($CH35,IF(T40-S40<0,-0.5,IF(S40-T40<0,0.5,0)),IF($CA35,IF($BR36>$BR37,-0.5,IF($BR36<$BR37,0.5,0)),IF($CD35,IF($BU36>$BU37,-0.5,IF($BU36<$BU37,0.5,0)),0))) -> 0 | CO36: =IF($CI35,IF(S38-T38<0,-0.5,IF(T38-S38<0,0.5,0)),IF($CB35,IF($BS36>$BS38,-0.5,IF($BS36<$BS38,0.5,0)),IF($CD35,IF($BU36>$BU38,-0.5,IF($BU36<$BU38,0.5,0)),0))) -> 0
A37: =IF(OR(ISBLANK(S37),ISBLANK(T37)),1,0) -> 1 | C37: 26 | D37: B3 | E37: Group | F37: Group B | G37: =R37 -> Canada | H37: =AN37 -> 2.2875624 | J37: Draw | K37: =AO37 -> 4.0093014 | M37: =U37 -> Qatar | N37: =AP37 -> 3.1931228 | P37: 46192 | Q37: 0 | R37: =R35 -> Canada | U37: =R36 -> Qatar | W37: =BA37 -> 1 | X37: =INDEX(BE35:BE38,MATCH(BC37,$BD35:$BD38,0)) -> Qatar | Y37: =INDEX(BF35:BF38,MATCH(BC37,$BD35:$BD38,0)) -> 0 | Z37: =INDEX(BG35:BG38,MATCH(BC37,$BD35:$BD38,0)) -> 0 | AA37: =INDEX(BH35:BH38,MATCH(BC37,$BD35:$BD38,0)) -> 0 | AB37: =INDEX(BI35:BI38,MATCH(BC37,$BD35:$BD38,0)) -> 0 | AE37: =R37 -> Canada | AF37: =U37 -> Qatar | AG37: =_xlfn.XLOOKUP(AE37,'FIFA rankings'!$B:$B,'FIFA rankings'!$D:$D) -> 1556.48 | AH37: =_xlfn.XLOOKUP(AF37,'FIFA rankings'!$B:$B,'FIFA rankings'!$D:$D) -> 1454.96 | AI37: =IFERROR(AG37-AH37,"n.a.") -> 101.52 | AK37: =IFERROR($AI$7*POWER(10,$AI37/$AI$6),"n.a.") -> 1.5442933 | AL37: =IFERROR($AI$7*POWER(10,-$AI37/$AI$6),"n.a.") -> 1.2691889 | AN37: {=1/SUMPRODUCT(_xlfn.POISSON.DIST(ROW($1:$8)-1,$AK37,FALSE)*_xlfn.POISSON.DIST(TRANSPOSE(ROW($1:$8)-1),$AL37,FALSE)*((ROW($1:$8)-1)>(TRANSPOSE(ROW($1:$8)-1))))} -> 2.2875624 | AO37: {=1/SUMPRODUCT(_xlfn.POISSON.DIST(ROW($1:$8)-1,$AK37,FALSE)*_xlfn.POISSON.DIST(TRANSPOSE(ROW($1:$8)-1),$AL37,FALSE)*((ROW($1:$8)-1)=(TRANSPOSE(ROW($1:$8)-1))))} -> 4.0093014 | AP37: {=1/SUMPRODUCT(_xlfn.POISSON.DIST(ROW($1:$8)-1,$AK37,FALSE)*_xlfn.POISSON.DIST(TRANSPOSE(ROW($1:$8)-1),$AL37,FALSE)*((ROW($1:$8)-1)<(TRANSPOSE(ROW($1:$8)-1))))} -> 3.1931228 | AS37: =1-SUM(1/AN37,1/AO37,1/AP37) -> 0.00026039646 | BA37: =IF(ROUND(BC37,0)=ROUND(BC36,0),BA36,3) -> 1 | BB37: =ROUND(BC37,0) -> 2 | BC37: =MIN(MAX(BD35:BD37),MAX(BD35,BD36,BD38),MAX(BD35,BD37,BD38),MAX(BD36:BD38)) -> 2.47 | BD37: =SUM(BV37:BY37)+2.47 -> 2.47 | BE37: =R36 -> Qatar | BF37: =SUM(BJ37:BM37) -> 0 | BG37: =S36+T37+T40 -> 0 | BH37: =T36+S37+S40 -> 0 | BI37: =BG37-BH37 -> 0 | BJ37: =IF(ISBLANK(T37),0,IF(BL35=3,0,IF(BL35=1,1,3))) -> 0 | BK37: =IF(ISBLANK(T40),0,IF(T40>S40,3,IF(T40=S40,1,0))) -> 0 | BL37: x | BM37: =IF(ISBLANK(S36),0,IF(S36>T36,3,IF(S36=T36,1,0))) -> 0 | BN37: =10*(BI35-BI37)+BG35-BG37<0 -> FALSE | BO37: =10*(BI36-BI37)+BG36-BG37<0 -> FALSE | BP37: x | BQ37: =10*(BI37-BI38)+BG37-BG38>0 -> FALSE | BR37: =10000*(BJ37+BK37)+(T37-S37+T40-S40)*100+(T37+T40) -> 0 | BS37: x | BT37: =10000*(BJ37+BM37)+(S36-T36+T37-S37)*100+(S36+T37) -> 0 | BU37: =10000*(BK37+BM37)+(S36-T36+T40-S40)*100+(S36+T40) -> 0 | BV37: =-BX35 -> 0 | BW37: =-BX36 -> 0 | BX37: x | BY37: =IF($BF37>$BF38,-0.5,IF($BF38>$BF37,0.5,IF(BQ37,-0.5,IF(BP38,0.5,CO37)))) -> 0 | CN37: x | CO37: =IF($CJ35,IF(T36-S36<0,-0.5,IF(S36-T36<0,0.5,0)),IF($CC35,IF($BT37>$BT38,-0.5,IF($BT37<$BT38,0.5,0)),IF($CD35,IF($BU37>$BU38,-0.5,IF($BU37<$BU38,0.5,0)),0))) -> 0
A38: =IF(OR(ISBLANK(S38),ISBLANK(T38)),1,0) -> 1 | C38: 27 | D38: B4 | E38: Group | F38: Group B | G38: =R38 -> Switzerland | H38: =AN38 -> 1.8453535 | J38: Draw | K38: =AO38 -> 4.333707 | M38: =U38 -> Bosnia and Herzegovina | N38: =AP38 -> 4.4100067 | P38: 46191 | Q38: 0.875 | R38: =U36 -> Switzerland | U38: =U35 -> Bosnia and Herzegovina | W38: =BA38 -> 1 | X38: =INDEX(BE35:BE38,MATCH(BC38,$BD35:$BD38,0)) -> Switzerland | Y38: =INDEX(BF35:BF38,MATCH(BC38,$BD35:$BD38,0)) -> 0 | Z38: =INDEX(BG35:BG38,MATCH(BC38,$BD35:$BD38,0)) -> 0 | AA38: =INDEX(BH35:BH38,MATCH(BC38,$BD35:$BD38,0)) -> 0 | AB38: =INDEX(BI35:BI38,MATCH(BC38,$BD35:$BD38,0)) -> 0 | AE38: =R38 -> Switzerland | AF38: =U38 -> Bosnia and Herzegovina | AG38: =_xlfn.XLOOKUP(AE38,'FIFA rankings'!$B:$B,'FIFA rankings'!$D:$D) -> 1649.4 | AH38: =_xlfn.XLOOKUP(AF38,'FIFA rankings'!$B:$B,'FIFA rankings'!$D:$D) -> 1385.84 | AI38: =IFERROR(AG38-AH38,"n.a.") -> 263.56 | AK38: =IFERROR($AI$7*POWER(10,$AI38/$AI$6),"n.a.") -> 1.8060431 | AL38: =IFERROR($AI$7*POWER(10,-$AI38/$AI$6),"n.a.") -> 1.0852454 | AN38: {=1/SUMPRODUCT(_xlfn.POISSON.DIST(ROW($1:$8)-1,$AK38,FALSE)*_xlfn.POISSON.DIST(TRANSPOSE(ROW($1:$8)-1),$AL38,FALSE)*((ROW($1:$8)-1)>(TRANSPOSE(ROW($1:$8)-1))))} -> 1.8453535 | AO38: {=1/SUMPRODUCT(_xlfn.POISSON.DIST(ROW($1:$8)-1,$AK38,FALSE)*_xlfn.POISSON.DIST(TRANSPOSE(ROW($1:$8)-1),$AL38,FALSE)*((ROW($1:$8)-1)=(TRANSPOSE(ROW($1:$8)-1))))} -> 4.333707 | AP38: {=1/SUMPRODUCT(_xlfn.POISSON.DIST(ROW($1:$8)-1,$AK38,FALSE)*_xlfn.POISSON.DIST(TRANSPOSE(ROW($1:$8)-1),$AL38,FALSE)*((ROW($1:$8)-1)<(TRANSPOSE(ROW($1:$8)-1))))} -> 4.4100067 | AS38: =1-SUM(1/AN38,1/AO38,1/AP38) -> 0.00059205576 | BA38: =IF(ROUND(BC38,0)=ROUND(BC37,0),BA37,4) -> 1 | BB38: =ROUND(BC38,0) -> 2 | BC38: =MAX(BD35:BD38) -> 2.48 | BD38: =SUM(BV38:BY38)+2.48 -> 2.48 | BE38: =U36 -> Switzerland | BF38: =SUM(BJ38:BM38) -> 0 | BG38: =T36+S38+S39 -> 0 | BH38: =S36+T38+T39 -> 0 | BI38: =BG38-BH38 -> 0 | BJ38: =IF(ISBLANK(S39),0,IF(BM35=3,0,IF(BM35=1,1,3))) -> 0 | BK38: =IF(ISBLANK(S38),0,IF(BM36=3,0,IF(BM36=1,1,3))) -> 0 | BL38: =IF(ISBLANK(T36),0,IF(BM37=3,0,IF(BM37=1,1,3))) -> 0 | BM38: x | BN38: =10*(BI35-BI38)+BG35-BG38<0 -> FALSE | BO38: =10*(BI36-BI38)+BG36-BG38<0 -> FALSE | BP38: =10*(BI37-BI38)+BG37-BG38<0 -> FALSE | BQ38: x | BR38: x | BS38: =10000*(BJ38+BK38)+(S38-T38+S39-T39)*100+(S38+S39) -> 0 | BT38: =10000*(BJ38+BL38)+(S39-T39+T36-S36)*100+(S39+T36) -> 0 | BU38: =10000*(BK38+BL38)+(S38-T38+T36-S36)*100+(S38+T36) -> 0 | BV38: =-BY35 -> 0 | BW38: =-BY36 -> 0 | BX38: =-BY37 -> 0 | BY38: x | CO38: x
A39: =IF(OR(ISBLANK(S39),ISBLANK(T39)),1,0) -> 1 | C39: 51 | E39: Group | F39: Group B | G39: =R39 -> Switzerland | H39: =AN39 -> 2.3166381 | J39: Draw | K39: =AO39 -> 4.0005349 | M39: =U39 -> Canada | N39: =AP39 -> 3.1434589 | P39: 46197 | Q39: 0.875 | R39: =U36 -> Switzerland | U39: =R35 -> Canada | X39: =IF(OR(W37<3,W36<2),"TIRAGE AU SORT !!!"," ") -> TIRAGE AU SORT !!! | AE39: =R39 -> Switzerland | AF39: =U39 -> Canada | AG39: =_xlfn.XLOOKUP(AE39,'FIFA rankings'!$B:$B,'FIFA rankings'!$D:$D) -> 1649.4 | AH39: =_xlfn.XLOOKUP(AF39,'FIFA rankings'!$B:$B,'FIFA rankings'!$D:$D) -> 1556.48 | AI39: =IFERROR(AG39-AH39,"n.a.") -> 92.92 | AK39: =IFERROR($AI$7*POWER(10,$AI39/$AI$6),"n.a.") -> 1.5315138 | AL39: =IFERROR($AI$7*POWER(10,-$AI39/$AI$6),"n.a.") -> 1.2797796 | AN39: {=1/SUMPRODUCT(_xlfn.POISSON.DIST(ROW($1:$8)-1,$AK39,FALSE)*_xlfn.POISSON.DIST(TRANSPOSE(ROW($1:$8)-1),$AL39,FALSE)*((ROW($1:$8)-1)>(TRANSPOSE(ROW($1:$8)-1))))} -> 2.3166381 | AO39: {=1/SUMPRODUCT(_xlfn.POISSON.DIST(ROW($1:$8)-1,$AK39,FALSE)*_xlfn.POISSON.DIST(TRANSPOSE(ROW($1:$8)-1),$AL39,FALSE)*((ROW($1:$8)-1)=(TRANSPOSE(ROW($1:$8)-1))))} -> 4.0005349 | AP39: {=1/SUMPRODUCT(_xlfn.POISSON.DIST(ROW($1:$8)-1,$AK39,FALSE)*_xlfn.POISSON.DIST(TRANSPOSE(ROW($1:$8)-1),$AL39,FALSE)*((ROW($1:$8)-1)<(TRANSPOSE(ROW($1:$8)-1))))} -> 3.1434589 | AS39: =1-SUM(1/AN39,1/AO39,1/AP39) -> 0.00025252091
A40: =IF(OR(ISBLANK(S40),ISBLANK(T40)),1,0) -> 1 | C40: 52 | E40: Group | F40: Group B | G40: =R40 -> Bosnia and Herzegovina | H40: =AN40 -> 3.0122292 | J40: Draw | K40: =AO40 -> 3.9803983 | M40: =U40 -> Qatar | N40: =AP40 -> 2.4006483 | P40: 46197 | Q40: 0.875 | R40: =U35 -> Bosnia and Herzegovina | U40: =R36 -> Qatar | AE40: =R40 -> Bosnia and Herzegovina | AF40: =U40 -> Qatar | AG40: =_xlfn.XLOOKUP(AE40,'FIFA rankings'!$B:$B,'FIFA rankings'!$D:$D) -> 1385.84 | AH40: =_xlfn.XLOOKUP(AF40,'FIFA rankings'!$B:$B,'FIFA rankings'!$D:$D) -> 1454.96 | AI40: =IFERROR(AG40-AH40,"n.a.") -> -69.12 | AK40: =IFERROR($AI$7*POWER(10,$AI40/$AI$6),"n.a.") -> 1.3095515 | AL40: =IFERROR($AI$7*POWER(10,-$AI40/$AI$6),"n.a.") -> 1.4966956 | AN40: {=1/SUMPRODUCT(_xlfn.POISSON.DIST(ROW($1:$8)-1,$AK40,FALSE)*_xlfn.POISSON.DIST(TRANSPOSE(ROW($1:$8)-1),$AL40,FALSE)*((ROW($1:$8)-1)>(TRANSPOSE(ROW($1:$8)-1))))} -> 3.0122292 | AO40: {=1/SUMPRODUCT(_xlfn.POISSON.DIST(ROW($1:$8)-1,$AK40,FALSE)*_xlfn.POISSON.DIST(TRANSPOSE(ROW($1:$8)-1),$AL40,FALSE)*((ROW($1:$8)-1)=(TRANSPOSE(ROW($1:$8)-1))))} -> 3.9803983 | AP40: {=1/SUMPRODUCT(_xlfn.POISSON.DIST(ROW($1:$8)-1,$AK40,FALSE)*_xlfn.POISSON.DIST(TRANSPOSE(ROW($1:$8)-1),$AL40,FALSE)*((ROW($1:$8)-1)<(TRANSPOSE(ROW($1:$8)-1))))} -> 2.4006483 | AS40: =1-SUM(1/AN40,1/AO40,1/AP40) -> 0.00023465321
F42: Group C | G42: =$F42 & " / Odds" -> Group C / Odds | P42: =$F42 & " / Results" -> Group C / Results | X42: =X34 -> Ranking | Y42: Pts | Z42: GF | AA42: GA | AB42: ="+/-" -> +/- | BD42: Rank | BE42: Team | BF42: Pts | BG42: GF | BH42: GA | BI42: GD | BJ42: Ag1 | BK42: Ag2 | BL42: Ag3 | BM42: Ag4 | BN42: Sp1 | BO42: Sp2 | BP42: Sp3 | BQ42: Sp4 | BR42: T123 | BS42: T124 | BT42: T134 | BU42: T234 | BV42: Rk1 | BW42: Rk2 | BX42: Rk3 | BY42: Rk4 | BZ42: T1234 | CA42: T123 | CB42: T124 | CC42: T134 | CD42: T234 | CE42: T12 | CF42: T13 | CG42: T14 | CH42: T23 | CI42: T24 | CJ42: T34 | CK42: NoT | CL42: sRk1 | CM42: sRk2 | CN42: sRk3 | CO42: sRk4
A43: =IF(OR(ISBLANK(S43),ISBLANK(T43)),1,0) -> 1 | C43: 5 | D43: C1 | E43: Group | F43: Group C | G43: =R43 -> Brazil | H43: =AN43 -> 2.6543707 | J43: Draw | K43: =AO43 -> 3.9557544 | M43: =U43 -> Morocco | N43: =AP43 -> 2.7008531 | P43: 46187 | Q43: 0 | R43: Brazil | U43: Morocco | W43: =BA43 -> 1 | X43: =INDEX(BE43:BE46,MATCH(BC43,$BD43:$BD46,0)) -> Brazil | Y43: =INDEX(BF43:BF46,MATCH(BC43,$BD43:$BD46,0)) -> 0 | Z43: =INDEX(BG43:BG46,MATCH(BC43,$BD43:$BD46,0)) -> 0 | AA43: =INDEX(BH43:BH46,MATCH(BC43,$BD43:$BD46,0)) -> 0 | AB43: =INDEX(BI43:BI46,MATCH(BC43,$BD43:$BD46,0)) -> 0 | AE43: =R43 -> Brazil | AF43: =U43 -> Morocco | AG43: =_xlfn.XLOOKUP(AE43,'FIFA rankings'!$B:$B,'FIFA rankings'!$D:$D) -> 1761.16 | AH43: =_xlfn.XLOOKUP(AF43,'FIFA rankings'!$B:$B,'FIFA rankings'!$D:$D) -> 1755.87 | AI43: =IFERROR(AG43-AH43,"n.a.") -> 5.29 | AK43: =IFERROR($AI$7*POWER(10,$AI43/$AI$6),"n.a.") -> 1.4071744 | AL43: =IFERROR($AI$7*POWER(10,-$AI43/$AI$6),"n.a.") -> 1.3928622 | AN43: {=1/SUMPRODUCT(_xlfn.POISSON.DIST(ROW($1:$8)-1,$AK43,FALSE)*_xlfn.POISSON.DIST(TRANSPOSE(ROW($1:$8)-1),$AL43,FALSE)*((ROW($1:$8)-1)>(TRANSPOSE(ROW($1:$8)-1))))} -> 2.6543707 | AO43: {=1/SUMPRODUCT(_xlfn.POISSON.DIST(ROW($1:$8)-1,$AK43,FALSE)*_xlfn.POISSON.DIST(TRANSPOSE(ROW($1:$8)-1),$AL43,FALSE)*((ROW($1:$8)-1)=(TRANSPOSE(ROW($1:$8)-1))))} -> 3.9557544 | AP43: {=1/SUMPRODUCT(_xlfn.POISSON.DIST(ROW($1:$8)-1,$AK43,FALSE)*_xlfn.POISSON.DIST(TRANSPOSE(ROW($1:$8)-1),$AL43,FALSE)*((ROW($1:$8)-1)<(TRANSPOSE(ROW($1:$8)-1))))} -> 2.7008531 | AS43: =1-SUM(1/AN43,1/AO43,1/AP43) -> 0.00021320921 | BA43: 1 | BB43: =ROUND(BC43,0) -> 2 | BC43: =MIN(BD43:BD46) -> 2.45 | BD43: =SUM(BV43:BY43)+2.45 -> 2.45 | BE43: =R43 -> Brazil | BF43: =SUM(BJ43:BM43) -> 0 | BG43: =S43+S45+T47 -> 0 | BH43: =T43+T45+S47 -> 0 | BI43: =BG43-BH43 -> 0 | BJ43: x | BK43: =IF(ISBLANK(S43),0,IF(S43>T43,3,IF(S43=T43,1,0))) -> 0 | BL43: =IF(ISBLANK(S45),0,IF(S45>T45,3,IF(S45=T45,1,0))) -> 0 | BM43: =IF(ISBLANK(T47),0,IF(T47>S47,3,IF(T47=S47,1,0))) -> 0 | BN43: x | BO43: =(10*(BI43-BI44)+BG43-BG44>0) -> FALSE | BP43: =10*(BI43-BI45)+BG43-BG45>0 -> FALSE | BQ43: =10*(BI43-BI46)+BG43-BG46>0 -> FALSE | BR43: =10000*(BK43+BL43)+(S45-T45+S43-T43)*100+(S45+S43) -> 0 | BS43: =10000*(BK43+BM43)+(S43-T43+T47-S47)*100+(S43+T47) -> 0 | BT43: =10000*(BL43+BM43)+(T47-S47+S45-T45)*100+(T47+S45) -> 0 | BU43: x | BV43: x | BW43: =IF($BF43>$BF44,-0.5,IF($BF44>$BF43,0.5,IF(BO43,-0.5,IF(BN44,0.5,CM43)))) -> 0 | BX43: =IF($BF43>$BF45,-0.5,IF($BF45>$BF43,0.5,IF(BP43,-0.5,IF(BN45,0.5,CN43)))) -> 0 | BY43: =IF($BF43>$BF46,-0.5,IF($BF46>$BF43,0.5,IF(BQ43,-0.5,IF(BN46,0.5,CO43)))) -> 0 | BZ43: =AND(AND(BF43=BF44,BF44=BF45,BF45=BF46),AND(BG43=BG44,BG44=BG45,BG45=BG46),AND(BH43=BH44,BH44=BH45,BH45=BH46)) -> TRUE | CA43: =AND(NOT(BZ43),BF43=BF44,BF43=BF45,BG43=BG44,BG43=BG45,BH43=BH44,BH43=BH45) -> FALSE | CB43: =AND(NOT(BZ43),BF43=BF44,BF43=BF46,BG43=BG44,BG43=BG46,BH43=BH44,BH43=BH46) -> FALSE | CC43: =AND(NOT(BZ43),BF43=BF45,BF43=BF46,BG43=BG45,BG43=BG46,BH43=BH45,BH43=BH46) -> FALSE | CD43: =AND(NOT(BZ43),BF44=BF45,BF44=BF46,BG44=BG45,BG44=BG46,BH44=BH45,BH44=BH46) -> FALSE | CE43: =AND(NOT(BZ43),NOT(CA43),NOT(CB43),BF43=BF44,BG43=BG44,BH43=BH44) -> FALSE | CF43: =AND(NOT(BZ43),NOT(CA43),NOT(CC43),BF43=BF45,BG43=BG45,BH43=BH45) -> FALSE | CG43: =AND(NOT(BZ43),NOT(CB43),NOT(CC43),BF43=BF46,BG43=BG46,BH43=BH46) -> FALSE | CH43: =AND(NOT(BZ43),NOT(CA43),NOT(CD43),BF44=BF45,BG44=BG45) -> FALSE | CI43: =AND(NOT(BZ43),NOT(CB43),NOT(CD43),BF44=BF46,BG44=BG46,BH44=BH46) -> FALSE | CJ43: =AND(NOT(BZ43),NOT(CC43),NOT(CD43),BF45=BF46,BG45=BG46,BH45=BH46) -> FALSE | CK43: {=AND(NOT(BZ43:CJ43))} -> FALSE | CL43: x | CM43: =IF($CE43,IF(T43-S43<0,-0.5,IF(S43-T43<0,0.5,0)),IF($CA43,IF($BR43>$BR44,-0.5,IF($BR43<$BR44,0.5,0)),IF($CB43,IF($BS43>$BS44,-0.5, IF($BS43<$BS44,0.5,0)),0))) -> 0 | CN43: =IF($CF43,IF(T45-S45<0,-0.5,IF(S45-T45<0,0.5,0)),IF($CA43,IF($BR43>$BR45,-0.5,IF($BR43<$BR45,0.5,0)),IF($CC43,IF($BT43>$BT45,-0.5,IF($BT43<$BT45,0.5,0)),0))) -> 0 | CO43: =IF($CG43,IF(S47-T47<0,-0.5,IF(T47-S47<0,0.5,0)),IF($CB43,IF($BS43>$BS46,-0.5,IF($BS43<$BS46,0.5,0)),IF($CC43,IF($BT43>$BT46,-0.5, IF($BT43<$BT46,0.5,0)),0))) -> 0
A44: =IF(OR(ISBLANK(S44),ISBLANK(T44)),1,0) -> 1 | C44: 7 | D44: C2 | E44: Group | F44: Group C | G44: =R44 -> Haiti | H44: =AN44 -> 3.9132362 | J44: Draw | K44: =AO44 -> 4.1834407 | M44: =U44 -> Scotland | N44: =AP44 -> 1.9802352 | P44: 46187 | Q44: 0.125 | R44: Haiti | U44: Scotland | W44: =BA44 -> 1 | X44: =INDEX(BE43:BE46,MATCH(BC44,$BD43:$BD46,0)) -> Morocco | Y44: =INDEX(BF43:BF46,MATCH(BC44,$BD43:$BD46,0)) -> 0 | Z44: =INDEX(BG43:BG46,MATCH(BC44,$BD43:$BD46,0)) -> 0 | AA44: =INDEX(BH43:BH46,MATCH(BC44,$BD43:$BD46,0)) -> 0 | AB44: =INDEX(BI43:BI46,MATCH(BC44,$BD43:$BD46,0)) -> 0 | AE44: =R44 -> Haiti | AF44: =U44 -> Scotland | AG44: =_xlfn.XLOOKUP(AE44,'FIFA rankings'!$B:$B,'FIFA rankings'!$D:$D) -> 1291.71 | AH44: =_xlfn.XLOOKUP(AF44,'FIFA rankings'!$B:$B,'FIFA rankings'!$D:$D) -> 1498.35 | AI44: =IFERROR(AG44-AH44,"n.a.") -> -206.64 | AK44: =IFERROR($AI$7*POWER(10,$AI44/$AI$6),"n.a.") -> 1.1466049 | AL44: =IFERROR($AI$7*POWER(10,-$AI44/$AI$6),"n.a.") -> 1.7093943 | AN44: {=1/SUMPRODUCT(_xlfn.POISSON.DIST(ROW($1:$8)-1,$AK44,FALSE)*_xlfn.POISSON.DIST(TRANSPOSE(ROW($1:$8)-1),$AL44,FALSE)*((ROW($1:$8)-1)>(TRANSPOSE(ROW($1:$8)-1))))} -> 3.9132362 | AO44: {=1/SUMPRODUCT(_xlfn.POISSON.DIST(ROW($1:$8)-1,$AK44,FALSE)*_xlfn.POISSON.DIST(TRANSPOSE(ROW($1:$8)-1),$AL44,FALSE)*((ROW($1:$8)-1)=(TRANSPOSE(ROW($1:$8)-1))))} -> 4.1834407 | AP44: {=1/SUMPRODUCT(_xlfn.POISSON.DIST(ROW($1:$8)-1,$AK44,FALSE)*_xlfn.POISSON.DIST(TRANSPOSE(ROW($1:$8)-1),$AL44,FALSE)*((ROW($1:$8)-1)<(TRANSPOSE(ROW($1:$8)-1))))} -> 1.9802352 | AS44: =1-SUM(1/AN44,1/AO44,1/AP44) -> 0.00042882518 | BA44: =IF(ROUND(BC44,0)=ROUND(BC43,0),BA43,2) -> 1 | BB44: =ROUND(BC44,0) -> 2 | BC44: =MAX(MIN(BD43:BD45),MIN(BD43,BD44,BD46),MIN(BD43,BD45,BD46),MIN(BD44:BD46)) -> 2.46 | BD44: =SUM(BV44:BY44)+2.46 -> 2.46 | BE44: =U43 -> Morocco | BF44: =SUM(BJ44:BM44) -> 0 | BG44: =T43+T46+S48 -> 0 | BH44: =S43+S46+T48 -> 0 | BI44: =BG44-BH44 -> 0 | BJ44: =IF(ISBLANK(T43),0,IF(BK43=3,0,IF(BK43=1,1,3))) -> 0 | BK44: x | BL44: =IF(ISBLANK(S48),0,IF(BK45=3,0,IF(BK45=1,1,3))) -> 0 | BM44: =IF(ISBLANK(T46),0,IF(T46>S46,3,IF(T46=S46,1,0))) -> 0 | BN44: =(10*(BI43-BI44)+BG43-BG44<0) -> FALSE | BO44: x | BP44: =10*(BI44-BI45)+BG44-BG45>0 -> FALSE | BQ44: =10*(BI44-BI46)+BG44-BG46>0 -> FALSE | BR44: =10000*(BJ44+BL44)+(T43-S43+S48-T48)*100+(T43+S48) -> 0 | BS44: =10000*(BJ44+BM44)+(T43-S43+T46-S46)*100+(T43+T46) -> 0 | BT44: x | BU44: =10000*(BL44+BM44)+(T46-S46+S48-T48)*100+(T46+S48) -> 0 | BV44: =-BW43 -> 0 | BW44: x | BX44: =IF($BF44>$BF45,-0.5,IF($BF45>$BF44,0.5,IF(BP44,-0.5,IF(BO45,0.5,CN44)))) -> 0 | BY44: =IF($BF44>$BF46,-0.5,IF($BF46>$BF44,0.5,IF(BQ44,-0.5,IF(BO46,0.5,CO44)))) -> 0 | CM44: x | CN44: =IF($CH43,IF(T48-S48<0,-0.5,IF(S48-T48<0,0.5,0)),IF($CA43,IF($BR44>$BR45,-0.5,IF($BR44<$BR45,0.5,0)),IF($CD43,IF($BU44>$BU45,-0.5,IF($BU44<$BU45,0.5,0)),0))) -> 0 | CO44: =IF($CI43,IF(S46-T46<0,-0.5,IF(T46-S46<0,0.5,0)),IF($CB43,IF($BS44>$BS46,-0.5,IF($BS44<$BS46,0.5,0)),IF($CD43,IF($BU44>$BU46,-0.5,IF($BU44<$BU46,0.5,0)),0))) -> 0
A45: =IF(OR(ISBLANK(S45),ISBLANK(T45)),1,0) -> 1 | C45: 29 | D45: C3 | E45: Group | F45: Group C | G45: =R45 -> Brazil | H45: =AN45 -> 1.490851 | J45: Draw | K45: =AO45 -> 5.3024703 | M45: =U45 -> Haiti | N45: =AP45 -> 7.2124486 | P45: 46193 | Q45: 0.125 | R45: =R43 -> Brazil | U45: =R44 -> Haiti | W45: =BA45 -> 1 | X45: =INDEX(BE43:BE46,MATCH(BC45,$BD43:$BD46,0)) -> Haiti | Y45: =INDEX(BF43:BF46,MATCH(BC45,$BD43:$BD46,0)) -> 0 | Z45: =INDEX(BG43:BG46,MATCH(BC45,$BD43:$BD46,0)) -> 0 | AA45: =INDEX(BH43:BH46,MATCH(BC45,$BD43:$BD46,0)) -> 0 | AB45: =INDEX(BI43:BI46,MATCH(BC45,$BD43:$BD46,0)) -> 0 | AE45: =R45 -> Brazil | AF45: =U45 -> Haiti | AG45: =_xlfn.XLOOKUP(AE45,'FIFA rankings'!$B:$B,'FIFA rankings'!$D:$D) -> 1761.16 | AH45: =_xlfn.XLOOKUP(AF45,'FIFA rankings'!$B:$B,'FIFA rankings'!$D:$D) -> 1291.71 | AI45: =IFERROR(AG45-AH45,"n.a.") -> 469.45 | AK45: =IFERROR($AI$7*POWER(10,$AI45/$AI$6),"n.a.") -> 2.2035739 | AL45: =IFERROR($AI$7*POWER(10,-$AI45/$AI$6),"n.a.") -> 0.88946416 | AN45: {=1/SUMPRODUCT(_xlfn.POISSON.DIST(ROW($1:$8)-1,$AK45,FALSE)*_xlfn.POISSON.DIST(TRANSPOSE(ROW($1:$8)-1),$AL45,FALSE)*((ROW($1:$8)-1)>(TRANSPOSE(ROW($1:$8)-1))))} -> 1.490851 | AO45: {=1/SUMPRODUCT(_xlfn.POISSON.DIST(ROW($1:$8)-1,$AK45,FALSE)*_xlfn.POISSON.DIST(TRANSPOSE(ROW($1:$8)-1),$AL45,FALSE)*((ROW($1:$8)-1)=(TRANSPOSE(ROW($1:$8)-1))))} -> 5.3024703 | AP45: {=1/SUMPRODUCT(_xlfn.POISSON.DIST(ROW($1:$8)-1,$AK45,FALSE)*_xlfn.POISSON.DIST(TRANSPOSE(ROW($1:$8)-1),$AL45,FALSE)*((ROW($1:$8)-1)<(TRANSPOSE(ROW($1:$8)-1))))} -> 7.2124486 | AS45: =1-SUM(1/AN45,1/AO45,1/AP45) -> 0.0020016522 | BA45: =IF(ROUND(BC45,0)=ROUND(BC44,0),BA44,3) -> 1 | BB45: =ROUND(BC45,0) -> 2 | BC45: =MIN(MAX(BD43:BD45),MAX(BD43,BD44,BD46),MAX(BD43,BD45,BD46),MAX(BD44:BD46)) -> 2.47 | BD45: =SUM(BV45:BY45)+2.47 -> 2.47 | BE45: =R44 -> Haiti | BF45: =SUM(BJ45:BM45) -> 0 | BG45: =S44+T45+T48 -> 0 | BH45: =T44+S45+S48 -> 0 | BI45: =BG45-BH45 -> 0 | BJ45: =IF(ISBLANK(T45),0,IF(BL43=3,0,IF(BL43=1,1,3))) -> 0 | BK45: =IF(ISBLANK(T48),0,IF(T48>S48,3,IF(T48=S48,1,0))) -> 0 | BL45: x | BM45: =IF(ISBLANK(S44),0,IF(S44>T44,3,IF(S44=T44,1,0))) -> 0 | BN45: =10*(BI43-BI45)+BG43-BG45<0 -> FALSE | BO45: =10*(BI44-BI45)+BG44-BG45<0 -> FALSE | BP45: x | BQ45: =10*(BI45-BI46)+BG45-BG46>0 -> FALSE | BR45: =10000*(BJ45+BK45)+(T45-S45+T48-S48)*100+(T45+T48) -> 0 | BS45: x | BT45: =10000*(BJ45+BM45)+(S44-T44+T45-S45)*100+(S44+T45) -> 0 | BU45: =10000*(BK45+BM45)+(S44-T44+T48-S48)*100+(S44+T48) -> 0 | BV45: =-BX43 -> 0 | BW45: =-BX44 -> 0 | BX45: x | BY45: =IF($BF45>$BF46,-0.5,IF($BF46>$BF45,0.5,IF(BQ45,-0.5,IF(BP46,0.5,CO45)))) -> 0 | CN45: x | CO45: =IF($CJ43,IF(T44-S44<0,-0.5,IF(S44-T44<0,0.5,0)),IF($CC43,IF($BT45>$BT46,-0.5,IF($BT45<$BT46,0.5,0)),IF($CD43,IF($BU45>$BU46,-0.5,IF($BU45<$BU46,0.5,0)),0))) -> 0
A46: =IF(OR(ISBLANK(S46),ISBLANK(T46)),1,0) -> 1 | C46: 30 | D46: C4 | E46: Group | F46: Group C | G46: =R46 -> Scotland | H46: =AN46 -> 4.3530255 | J46: Draw | K46: =AO46 -> 4.3157271 | M46: =U46 -> Morocco | N46: =AP46 -> 1.8587624 | P46: 46193 | Q46: 0 | R46: =U44 -> Scotland | U46: =U43 -> Morocco | W46: =BA46 -> 1 | X46: =INDEX(BE43:BE46,MATCH(BC46,$BD43:$BD46,0)) -> Scotland | Y46: =INDEX(BF43:BF46,MATCH(BC46,$BD43:$BD46,0)) -> 0 | Z46: =INDEX(BG43:BG46,MATCH(BC46,$BD43:$BD46,0)) -> 0 | AA46: =INDEX(BH43:BH46,MATCH(BC46,$BD43:$BD46,0)) -> 0 | AB46: =INDEX(BI43:BI46,MATCH(BC46,$BD43:$BD46,0)) -> 0 | AE46: =R46 -> Scotland | AF46: =U46 -> Morocco | AG46: =_xlfn.XLOOKUP(AE46,'FIFA rankings'!$B:$B,'FIFA rankings'!$D:$D) -> 1498.35 | AH46: =_xlfn.XLOOKUP(AF46,'FIFA rankings'!$B:$B,'FIFA rankings'!$D:$D) -> 1755.87 | AI46: =IFERROR(AG46-AH46,"n.a.") -> -257.52 | AK46: =IFERROR($AI$7*POWER(10,$AI46/$AI$6),"n.a.") -> 1.0915976 | AL46: =IFERROR($AI$7*POWER(10,-$AI46/$AI$6),"n.a.") -> 1.7955334 | AN46: {=1/SUMPRODUCT(_xlfn.POISSON.DIST(ROW($1:$8)-1,$AK46,FALSE)*_xlfn.POISSON.DIST(TRANSPOSE(ROW($1:$8)-1),$AL46,FALSE)*((ROW($1:$8)-1)>(TRANSPOSE(ROW($1:$8)-1))))} -> 4.3530255 | AO46: {=1/SUMPRODUCT(_xlfn.POISSON.DIST(ROW($1:$8)-1,$AK46,FALSE)*_xlfn.POISSON.DIST(TRANSPOSE(ROW($1:$8)-1),$AL46,FALSE)*((ROW($1:$8)-1)=(TRANSPOSE(ROW($1:$8)-1))))} -> 4.3157271 | AP46: {=1/SUMPRODUCT(_xlfn.POISSON.DIST(ROW($1:$8)-1,$AK46,FALSE)*_xlfn.POISSON.DIST(TRANSPOSE(ROW($1:$8)-1),$AL46,FALSE)*((ROW($1:$8)-1)<(TRANSPOSE(ROW($1:$8)-1))))} -> 1.8587624 | AS46: =1-SUM(1/AN46,1/AO46,1/AP46) -> 0.00057167244 | BA46: =IF(ROUND(BC46,0)=ROUND(BC45,0),BA45,4) -> 1 | BB46: =ROUND(BC46,0) -> 2 | BC46: =MAX(BD43:BD46) -> 2.48 | BD46: =SUM(BV46:BY46)+2.48 -> 2.48 | BE46: =U44 -> Scotland | BF46: =SUM(BJ46:BM46) -> 0 | BG46: =T44+S46+S47 -> 0 | BH46: =S44+T46+T47 -> 0 | BI46: =BG46-BH46 -> 0 | BJ46: =IF(ISBLANK(S47),0,IF(BM43=3,0,IF(BM43=1,1,3))) -> 0 | BK46: =IF(ISBLANK(S46),0,IF(BM44=3,0,IF(BM44=1,1,3))) -> 0 | BL46: =IF(ISBLANK(T44),0,IF(BM45=3,0,IF(BM45=1,1,3))) -> 0 | BM46: x | BN46: =10*(BI43-BI46)+BG43-BG46<0 -> FALSE | BO46: =10*(BI44-BI46)+BG44-BG46<0 -> FALSE | BP46: =10*(BI45-BI46)+BG45-BG46<0 -> FALSE | BQ46: x | BR46: x | BS46: =10000*(BJ46+BK46)+(S46-T46+S47-T47)*100+(S46+S47) -> 0 | BT46: =10000*(BJ46+BL46)+(S47-T47+T44-S44)*100+(S47+T44) -> 0 | BU46: =10000*(BK46+BL46)+(S46-T46+T44-S44)*100+(S46+T44) -> 0 | BV46: =-BY43 -> 0 | BW46: =-BY44 -> 0 | BX46: =-BY45 -> 0 | BY46: x | CO46: x
A47: =IF(OR(ISBLANK(S47),ISBLANK(T47)),1,0) -> 1 | C47: 49 | E47: Group | F47: Group C | G47: =R47 -> Scotland | H47: =AN47 -> 4.4028722 | J47: Draw | K47: =AO47 -> 4.3314471 | M47: =U47 -> Brazil | N47: =AP47 -> 1.8470075 | P47: 46198 | Q47: 0 | R47: =U44 -> Scotland | U47: =R43 -> Brazil | X47: =IF(OR(W45<3,W44<2),"TIRAGE AU SORT !!!"," ") -> TIRAGE AU SORT !!! | AE47: =R47 -> Scotland | AF47: =U47 -> Brazil | AG47: =_xlfn.XLOOKUP(AE47,'FIFA rankings'!$B:$B,'FIFA rankings'!$D:$D) -> 1498.35 | AH47: =_xlfn.XLOOKUP(AF47,'FIFA rankings'!$B:$B,'FIFA rankings'!$D:$D) -> 1761.16 | AI47: =IFERROR(AG47-AH47,"n.a.") -> -262.81 | AK47: =IFERROR($AI$7*POWER(10,$AI47/$AI$6),"n.a.") -> 1.0860321 | AL47: =IFERROR($AI$7*POWER(10,-$AI47/$AI$6),"n.a.") -> 1.8047348 | AN47: {=1/SUMPRODUCT(_xlfn.POISSON.DIST(ROW($1:$8)-1,$AK47,FALSE)*_xlfn.POISSON.DIST(TRANSPOSE(ROW($1:$8)-1),$AL47,FALSE)*((ROW($1:$8)-1)>(TRANSPOSE(ROW($1:$8)-1))))} -> 4.4028722 | AO47: {=1/SUMPRODUCT(_xlfn.POISSON.DIST(ROW($1:$8)-1,$AK47,FALSE)*_xlfn.POISSON.DIST(TRANSPOSE(ROW($1:$8)-1),$AL47,FALSE)*((ROW($1:$8)-1)=(TRANSPOSE(ROW($1:$8)-1))))} -> 4.3314471 | AP47: {=1/SUMPRODUCT(_xlfn.POISSON.DIST(ROW($1:$8)-1,$AK47,FALSE)*_xlfn.POISSON.DIST(TRANSPOSE(ROW($1:$8)-1),$AL47,FALSE)*((ROW($1:$8)-1)<(TRANSPOSE(ROW($1:$8)-1))))} -> 1.8470075 | AS47: =1-SUM(1/AN47,1/AO47,1/AP47) -> 0.00058948125
A48: =IF(OR(ISBLANK(S48),ISBLANK(T48)),1,0) -> 1 | C48: 50 | E48: Group | F48: Group C | G48: =R48 -> Morocco | H48: =AN48 -> 1.4978624 | J48: Draw | K48: =AO48 -> 5.2671853 | M48: =U48 -> Haiti | N48: =AP48 -> 7.1130475 | P48: 46198 | Q48: 0 | R48: =U43 -> Morocco | U48: =R44 -> Haiti | AE48: =R48 -> Morocco | AF48: =U48 -> Haiti | AG48: =_xlfn.XLOOKUP(AE48,'FIFA rankings'!$B:$B,'FIFA rankings'!$D:$D) -> 1755.87 | AH48: =_xlfn.XLOOKUP(AF48,'FIFA rankings'!$B:$B,'FIFA rankings'!$D:$D) -> 1291.71 | AI48: =IFERROR(AG48-AH48,"n.a.") -> 464.16 | AK48: =IFERROR($AI$7*POWER(10,$AI48/$AI$6),"n.a.") -> 2.1923391 | AL48: =IFERROR($AI$7*POWER(10,-$AI48/$AI$6),"n.a.") -> 0.89402229 | AN48: {=1/SUMPRODUCT(_xlfn.POISSON.DIST(ROW($1:$8)-1,$AK48,FALSE)*_xlfn.POISSON.DIST(TRANSPOSE(ROW($1:$8)-1),$AL48,FALSE)*((ROW($1:$8)-1)>(TRANSPOSE(ROW($1:$8)-1))))} -> 1.4978624 | AO48: {=1/SUMPRODUCT(_xlfn.POISSON.DIST(ROW($1:$8)-1,$AK48,FALSE)*_xlfn.POISSON.DIST(TRANSPOSE(ROW($1:$8)-1),$AL48,FALSE)*((ROW($1:$8)-1)=(TRANSPOSE(ROW($1:$8)-1))))} -> 5.2671853 | AP48: {=1/SUMPRODUCT(_xlfn.POISSON.DIST(ROW($1:$8)-1,$AK48,FALSE)*_xlfn.POISSON.DIST(TRANSPOSE(ROW($1:$8)-1),$AL48,FALSE)*((ROW($1:$8)-1)<(TRANSPOSE(ROW($1:$8)-1))))} -> 7.1130475 | AS48: =1-SUM(1/AN48,1/AO48,1/AP48) -> 0.0019404824
F50: Group D | G50: =$F50 & " / Odds" -> Group D / Odds | P50: =$F50 & " / Results" -> Group D / Results | X50: =X42 -> Ranking | Y50: Pts | Z50: GF | AA50: GA | AB50: ="+/-" -> +/- | BD50: Rank | BE50: Team | BF50: Pts | BG50: GF | BH50: GA | BI50: GD | BJ50: Ag1 | BK50: Ag2 | BL50: Ag3 | BM50: Ag4 | BN50: Sp1 | BO50: Sp2 | BP50: Sp3 | BQ50: Sp4 | BR50: T123 | BS50: T124 | BT50: T134 | BU50: T234 | BV50: Rk1 | BW50: Rk2 | BX50: Rk3 | BY50: Rk4 | BZ50: T1234 | CA50: T123 | CB50: T124 | CC50: T134 | CD50: T234 | CE50: T12 | CF50: T13 | CG50: T14 | CH50: T23 | CI50: T24 | CJ50: T34 | CK50: NoT | CL50: sRk1 | CM50: sRk2 | CN50: sRk3 | CO50: sRk4
A51: =IF(OR(ISBLANK(S51),ISBLANK(T51)),1,0) -> 1 | C51: 4 | D51: D1 | E51: Group | F51: Group D | G51: =R51 -> USA | H51: =AN51 -> 2.0790397 | J51: Draw | K51: =AO51 -> 4.1075642 | M51: =U51 -> Paraguay | N51: =AP51 -> 3.6336844 | P51: 46186 | Q51: 0.125 | R51: USA | U51: Paraguay | W51: =BA51 -> 1 | X51: =INDEX(BE51:BE54,MATCH(BC51,$BD51:$BD54,0)) -> USA | Y51: =INDEX(BF51:BF54,MATCH(BC51,$BD51:$BD54,0)) -> 0 | Z51: =INDEX(BG51:BG54,MATCH(BC51,$BD51:$BD54,0)) -> 0 | AA51: =INDEX(BH51:BH54,MATCH(BC51,$BD51:$BD54,0)) -> 0 | AB51: =INDEX(BI51:BI54,MATCH(BC51,$BD51:$BD54,0)) -> 0 | AE51: =R51 -> USA | AF51: =U51 -> Paraguay | AG51: =_xlfn.XLOOKUP(AE51,'FIFA rankings'!$B:$B,'FIFA rankings'!$D:$D) -> 1673.13 | AH51: =_xlfn.XLOOKUP(AF51,'FIFA rankings'!$B:$B,'FIFA rankings'!$D:$D) -> 1503.5 | AI51: =IFERROR(AG51-AH51,"n.a.") -> 169.63 | AK51: =IFERROR($AI$7*POWER(10,$AI51/$AI$6),"n.a.") -> 1.6493447 | AL51: =IFERROR($AI$7*POWER(10,-$AI51/$AI$6),"n.a.") -> 1.1883508 | AN51: {=1/SUMPRODUCT(_xlfn.POISSON.DIST(ROW($1:$8)-1,$AK51,FALSE)*_xlfn.POISSON.DIST(TRANSPOSE(ROW($1:$8)-1),$AL51,FALSE)*((ROW($1:$8)-1)>(TRANSPOSE(ROW($1:$8)-1))))} -> 2.0790397 | AO51: {=1/SUMPRODUCT(_xlfn.POISSON.DIST(ROW($1:$8)-1,$AK51,FALSE)*_xlfn.POISSON.DIST(TRANSPOSE(ROW($1:$8)-1),$AL51,FALSE)*((ROW($1:$8)-1)=(TRANSPOSE(ROW($1:$8)-1))))} -> 4.1075642 | AP51: {=1/SUMPRODUCT(_xlfn.POISSON.DIST(ROW($1:$8)-1,$AK51,FALSE)*_xlfn.POISSON.DIST(TRANSPOSE(ROW($1:$8)-1),$AL51,FALSE)*((ROW($1:$8)-1)<(TRANSPOSE(ROW($1:$8)-1))))} -> 3.6336844 | AS51: =1-SUM(1/AN51,1/AO51,1/AP51) -> 0.00035265263 | BA51: 1 | BB51: =ROUND(BC51,0) -> 2 | BC51: =MIN(BD51:BD54) -> 2.45 | BD51: =SUM(BV51:BY51)+2.45 -> 2.45 | BE51: =R51 -> USA | BF51: =SUM(BJ51:BM51) -> 0 | BG51: =S51+S53+T55 -> 0 | BH51: =T51+T53+S55 -> 0 | BI51: =BG51-BH51 -> 0 | BJ51: x | BK51: =IF(ISBLANK(S51),0,IF(S51>T51,3,IF(S51=T51,1,0))) -> 0 | BL51: =IF(ISBLANK(S53),0,IF(S53>T53,3,IF(S53=T53,1,0))) -> 0 | BM51: =IF(ISBLANK(T55),0,IF(T55>S55,3,IF(T55=S55,1,0))) -> 0 | BN51: x | BO51: =(10*(BI51-BI52)+BG51-BG52>0) -> FALSE | BP51: =10*(BI51-BI53)+BG51-BG53>0 -> FALSE | BQ51: =10*(BI51-BI54)+BG51-BG54>0 -> FALSE | BR51: =10000*(BK51+BL51)+(S53-T53+S51-T51)*100+(S53+S51) -> 0 | BS51: =10000*(BK51+BM51)+(S51-T51+T55-S55)*100+(S51+T55) -> 0 | BT51: =10000*(BL51+BM51)+(T55-S55+S53-T53)*100+(T55+S53) -> 0 | BU51: x | BV51: x | BW51: =IF($BF51>$BF52,-0.5,IF($BF52>$BF51,0.5,IF(BO51,-0.5,IF(BN52,0.5,CM51)))) -> 0 | BX51: =IF($BF51>$BF53,-0.5,IF($BF53>$BF51,0.5,IF(BP51,-0.5,IF(BN53,0.5,CN51)))) -> 0 | BY51: =IF($BF51>$BF54,-0.5,IF($BF54>$BF51,0.5,IF(BQ51,-0.5,IF(BN54,0.5,CO51)))) -> 0 | BZ51: =AND(AND(BF51=BF52,BF52=BF53,BF53=BF54),AND(BG51=BG52,BG52=BG53,BG53=BG54),AND(BH51=BH52,BH52=BH53,BH53=BH54)) -> TRUE | CA51: =AND(NOT(BZ51),BF51=BF52,BF51=BF53,BG51=BG52,BG51=BG53,BH51=BH52,BH51=BH53) -> FALSE | CB51: =AND(NOT(BZ51),BF51=BF52,BF51=BF54,BG51=BG52,BG51=BG54,BH51=BH52,BH51=BH54) -> FALSE | CC51: =AND(NOT(BZ51),BF51=BF53,BF51=BF54,BG51=BG53,BG51=BG54,BH51=BH53,BH51=BH54) -> FALSE | CD51: =AND(NOT(BZ51),BF52=BF53,BF52=BF54,BG52=BG53,BG52=BG54,BH52=BH53,BH52=BH54) -> FALSE | CE51: =AND(NOT(BZ51),NOT(CA51),NOT(CB51),BF51=BF52,BG51=BG52,BH51=BH52) -> FALSE | CF51: =AND(NOT(BZ51),NOT(CA51),NOT(CC51),BF51=BF53,BG51=BG53,BH51=BH53) -> FALSE | CG51: =AND(NOT(BZ51),NOT(CB51),NOT(CC51),BF51=BF54,BG51=BG54,BH51=BH54) -> FALSE | CH51: =AND(NOT(BZ51),NOT(CA51),NOT(CD51),BF52=BF53,BG52=BG53) -> FALSE | CI51: =AND(NOT(BZ51),NOT(CB51),NOT(CD51),BF52=BF54,BG52=BG54,BH52=BH54) -> FALSE | CJ51: =AND(NOT(BZ51),NOT(CC51),NOT(CD51),BF53=BF54,BG53=BG54,BH53=BH54) -> FALSE | CK51: {=AND(NOT(BZ51:CJ51))} -> FALSE | CL51: x | CM51: =IF($CE51,IF(T51-S51<0,-0.5,IF(S51-T51<0,0.5,0)),IF($CA51,IF($BR51>$BR52,-0.5,IF($BR51<$BR52,0.5,0)),IF($CB51,IF($BS51>$BS52,-0.5, IF($BS51<$BS52,0.5,0)),0))) -> 0 | CN51: =IF($CF51,IF(T53-S53<0,-0.5,IF(S53-T53<0,0.5,0)),IF($CA51,IF($BR51>$BR53,-0.5,IF($BR51<$BR53,0.5,0)),IF($CC51,IF($BT51>$BT53,-0.5,IF($BT51<$BT53,0.5,0)),0))) -> 0 | CO51: =IF($CG51,IF(S55-T55<0,-0.5,IF(T55-S55<0,0.5,0)),IF($CB51,IF($BS51>$BS54,-0.5,IF($BS51<$BS54,0.5,0)),IF($CC51,IF($BT51>$BT54,-0.5, IF($BT51<$BT54,0.5,0)),0))) -> 0
A52: =IF(OR(ISBLANK(S52),ISBLANK(T52)),1,0) -> 1 | C52: 6 | D52: D2 | E52: Group | F52: Group D | G52: =R52 -> Australia | H52: =AN52 -> 2.7602254 | J52: Draw | K52: =AO52 -> 3.957355 | M52: =U52 -> Türkiye | N52: =AP52 -> 2.5987383 | P52: 46187 | Q52: 0.25 | R52: Australia | U52: Türkiye | W52: =BA52 -> 1 | X52: =INDEX(BE51:BE54,MATCH(BC52,$BD51:$BD54,0)) -> Paraguay | Y52: =INDEX(BF51:BF54,MATCH(BC52,$BD51:$BD54,0)) -> 0 | Z52: =INDEX(BG51:BG54,MATCH(BC52,$BD51:$BD54,0)) -> 0 | AA52: =INDEX(BH51:BH54,MATCH(BC52,$BD51:$BD54,0)) -> 0 | AB52: =INDEX(BI51:BI54,MATCH(BC52,$BD51:$BD54,0)) -> 0 | AE52: =R52 -> Australia | AF52: =U52 -> Türkiye | AG52: =_xlfn.XLOOKUP(AE52,'FIFA rankings'!$B:$B,'FIFA rankings'!$D:$D) -> 1580.67 | AH52: =_xlfn.XLOOKUP(AF52,'FIFA rankings'!$B:$B,'FIFA rankings'!$D:$D) -> 1599.04 | AI52: =IFERROR(AG52-AH52,"n.a.") -> -18.37 | AK52: =IFERROR($AI$7*POWER(10,$AI52/$AI$6),"n.a.") -> 1.3753691 | AL52: =IFERROR($AI$7*POWER(10,-$AI52/$AI$6),"n.a.") -> 1.425072 | AN52: {=1/SUMPRODUCT(_xlfn.POISSON.DIST(ROW($1:$8)-1,$AK52,FALSE)*_xlfn.POISSON.DIST(TRANSPOSE(ROW($1:$8)-1),$AL52,FALSE)*((ROW($1:$8)-1)>(TRANSPOSE(ROW($1:$8)-1))))} -> 2.7602254 | AO52: {=1/SUMPRODUCT(_xlfn.POISSON.DIST(ROW($1:$8)-1,$AK52,FALSE)*_xlfn.POISSON.DIST(TRANSPOSE(ROW($1:$8)-1),$AL52,FALSE)*((ROW($1:$8)-1)=(TRANSPOSE(ROW($1:$8)-1))))} -> 3.957355 | AP52: {=1/SUMPRODUCT(_xlfn.POISSON.DIST(ROW($1:$8)-1,$AK52,FALSE)*_xlfn.POISSON.DIST(TRANSPOSE(ROW($1:$8)-1),$AL52,FALSE)*((ROW($1:$8)-1)<(TRANSPOSE(ROW($1:$8)-1))))} -> 2.5987383 | AS52: =1-SUM(1/AN52,1/AO52,1/AP52) -> 0.00021458773 | BA52: =IF(ROUND(BC52,0)=ROUND(BC51,0),BA51,2) -> 1 | BB52: =ROUND(BC52,0) -> 2 | BC52: =MAX(MIN(BD51:BD53),MIN(BD51,BD52,BD54),MIN(BD51,BD53,BD54),MIN(BD52:BD54)) -> 2.46 | BD52: =SUM(BV52:BY52)+2.46 -> 2.46 | BE52: =U51 -> Paraguay | BF52: =SUM(BJ52:BM52) -> 0 | BG52: =T51+T54+S56 -> 0 | BH52: =S51+S54+T56 -> 0 | BI52: =BG52-BH52 -> 0 | BJ52: =IF(ISBLANK(T51),0,IF(BK51=3,0,IF(BK51=1,1,3))) -> 0 | BK52: x | BL52: =IF(ISBLANK(S56),0,IF(BK53=3,0,IF(BK53=1,1,3))) -> 0 | BM52: =IF(ISBLANK(T54),0,IF(T54>S54,3,IF(T54=S54,1,0))) -> 0 | BN52: =(10*(BI51-BI52)+BG51-BG52<0) -> FALSE | BO52: x | BP52: =10*(BI52-BI53)+BG52-BG53>0 -> FALSE | BQ52: =10*(BI52-BI54)+BG52-BG54>0 -> FALSE | BR52: =10000*(BJ52+BL52)+(T51-S51+S56-T56)*100+(T51+S56) -> 0 | BS52: =10000*(BJ52+BM52)+(T51-S51+T54-S54)*100+(T51+T54) -> 0 | BT52: x | BU52: =10000*(BL52+BM52)+(T54-S54+S56-T56)*100+(T54+S56) -> 0 | BV52: =-BW51 -> 0 | BW52: x | BX52: =IF($BF52>$BF53,-0.5,IF($BF53>$BF52,0.5,IF(BP52,-0.5,IF(BO53,0.5,CN52)))) -> 0 | BY52: =IF($BF52>$BF54,-0.5,IF($BF54>$BF52,0.5,IF(BQ52,-0.5,IF(BO54,0.5,CO52)))) -> 0 | CM52: x | CN52: =IF($CH51,IF(T56-S56<0,-0.5,IF(S56-T56<0,0.5,0)),IF($CA51,IF($BR52>$BR53,-0.5,IF($BR52<$BR53,0.5,0)),IF($CD51,IF($BU52>$BU53,-0.5,IF($BU52<$BU53,0.5,0)),0))) -> 0 | CO52: =IF($CI51,IF(S54-T54<0,-0.5,IF(T54-S54<0,0.5,0)),IF($CB51,IF($BS52>$BS54,-0.5,IF($BS52<$BS54,0.5,0)),IF($CD51,IF($BU52>$BU54,-0.5,IF($BU52<$BU54,0.5,0)),0))) -> 0
